Workbook

Sheet Names
A3: NAMES | L3: INFORMATION
A4: Boys | F4: Girls | L4: SCHOOL ID
A5: 1 | F5: 1 | L5: SCHOOL YEAR
A6: 2 | F6: 2 | L6: GRADE LEVEL
A7: 3 | F7: 3 | L7: SECTION
A8: 4 | F8: 4 | L8: NAME OF SCHOOL
A9: 5 | F9: 5 | L9: GRADE AND SECTION
A10: 6 | F10: 6 | L10: TEACHER-IN-CHARGE
A11: 7 | F11: 7 | L11: SCHOOL HEAD / PRINCIPAL
A12: 8 | F12: 8
A13: 9 | F13: 9
A14: 10 | F14: 10
A15: 11 | F15: 11
A16: 12 | F16: 12
A17: 13 | F17: 13
A18: 14 | F18: 14
A19: 15 | F19: 15
A20: 16 | F20: 16
A21: 17 | F21: 17
A22: 18 | F22: 18
A23: 19 | F23: 19
... A44: 40 | F44: 40

Sheet Holidays
B2: =VLOOKUP(C2,I2:J13,2,0) | C2: JUNE | I2: January | J2: 2015 | K2: 1
I3: February | J3: 2015 | K3: 2
A4: National and Local Holidays | I4: March | J4: 2015
A5: # | B5: Month | C5: Date | D5: REASON | I5: April | J5: 2015
A6: =IF(B6="","",1) | B6: June | C6: 12 | D6: Independence Day | F6: =IF(B6=$C$2,C6,0) | G6: =DATE(B2,B6,C6) | I6: May | J6: 2015
A7: =IF(B7="","",A6+1) | B7: July | C7: 25 | D7: Eidl Ftr | F7: =IF(B7=$C$2,C7,0) | I7: June | J7: 2014
A8: =IF(B8="","",A7+1) | B8: July | C8: 16 | D8: Class Suspended due to Typhoon | F8: =IF(B8=$C$2,C8,0) | I8: July | J8: 2014
A9: =IF(B9="","",A8+1) | B9: August | C9: 6 | D9: Cebu Charter Day | F9: =IF(B9=$C$2,C9,0) | I9: August | J9: 2014
A10: =IF(B10="","",A9+1) | B10: August | C10: 21 | D10: Ninoy Aquino Day | F10: =IF(B10=$C$2,C10,0) | I10: September | J10: 2014
A11: =IF(B11="","",A10+1) | B11: August | C11: 25 | D11: National Heroes Day | F11: =IF(B11=$C$2,C11,0) | I11: October | J11: 2014
A12: =IF(B12="","",A11+1) | B12: November | C12: 1 | D12: All Saints Day | F12: =IF(B12=$C$2,C12,0) | I12: November | J12: 2014
A13: =IF(B13="","",A12+1) | B13: November | C13: 2 | D13: All Souls Day | F13: =IF(B13=$C$2,C13,0) | I13: December | J13: 2014
A14: =IF(B14="","",A13+1) | B14: November | C14: 30 | D14: Bonifacio Day | F14: =IF(B14=$C$2,C14,0)
A15: =IF(B15="","",A14+1) | B15: December | C15: 24 | D15: Special Non-Working Holiday | F15: =IF(B15=$C$2,C15,0)
A16: =IF(B16="","",A15+1) | B16: December | C16: 25 | D16: Christmas Day | F16: =IF(B16=$C$2,C16,0)
A17: =IF(B17="","",A16+1) | B17: December | C17: 26 | D17: Special Non-Working Holiday | F17: =IF(B17=$C$2,C17,0)
A18: =IF(B18="","",A17+1) | B18: December | C18: 30 | D18: Rizal Day | F18: =IF(B18=$C$2,C18,0)
A19: =IF(B19="","",A18+1) | B19: December | C19: 31 | D19: Special Non-Working Holiday | F19: =IF(B19=$C$2,C19,0)
A20: =IF(B20="","",A19+1) | B20: January | C20: 31 | D20: Chinese New Year | F20: =IF(B20=$C$2,C20,0)
A21: =IF(B21="","",A20+1) | B21: February | C21: 25 | D21: EDSA Revolution | F21: =IF(B21=$C$2,C21,0)
A22: =IF(B22="","",A21+1) | B22: October | C22: 6 | D22: Holiday | F22: =IF(B22=$C$2,C22,0)
A23: =IF(B23="","",A22+1) | B23: November | C23: 27 | D23: Class Suspended due to Queenie | F23: =IF(B23=$C$2,C23,0)
A24: =IF(B24="","",A23+1) | B24: December | C24: 5 | D24: Class Suspended due to Typhoon | F24: =IF(B24=$C$2,C24,0)
A25: =IF(B25="","",A24+1) | B25: December | C25: 8 | D25: Class Suspended due to Typhoon | F25: =IF(B25=$C$2,C25,0)
... A32: =IF(B32="","",A31+1) | B32: July | C32: 3 | D32: no class | F32: =IF(B32=$C$2,C32,0)
A33: =IF(B33="","",A32+1) | F33: =IF(B33=$C$2,C33,0)
A34: =IF(B34="","",A33+1) | F34: =IF(B34=$C$2,C34,0)
A35: =IF(B35="","",A34+1) | F35: =IF(B35=$C$2,C35,0)
A36: =IF(B36="","",A35+1) | F36: =IF(B36=$C$2,C36,0)
A37: =IF(B37="","",A36+1) | F37: =IF(B37=$C$2,C37,0)
A38: =IF(B38="","",A37+1) | F38: =IF(B38=$C$2,C38,0)
A39: =IF(B39="","",A38+1) | F39: =IF(B39=$C$2,C39,0)
A40: =IF(B40="","",A39+1) | F40: =IF(B40=$C$2,C40,0)
A41: =IF(B41="","",A40+1) | F41: =IF(B41=$C$2,C41,0)
A42: =IF(B42="","",A41+1) | F42: =IF(B42=$C$2,C42,0)
A43: =IF(B43="","",A42+1) | F43: =IF(B43=$C$2,C43,0)
A44: =IF(B44="","",A43+1) | F44: =IF(B44=$C$2,C44,0)
... A55: =IF(B55="","",A54+1) | F55: =IF(B55=$C$2,C55,0)

Sheet SF2 (JUN)
A2: School Form 2 (SF2) Daily Attendance Report of Learners | AY2: MONTH | AZ2: =IF(AG6="","",VLOOKUP(AG6,AY13:AZ25,2,0)) | BA2: YEAR | BB2: =VLOOKUP(AZ2,AZ13:BA24,2,0) | BC2: DATE | BD2: =DATE(BB2,AZ2,1)
A3: (This replaces Form 1, Form 2 & STS Form 4 - Absenteeism and Dropout Profile) | AY3: YEAR | AZ3: =CONCATENATE(AY8,AZ8,BA8,BB8)
B6: School ID | C6: =IF(Names!Q4="","",Names!Q4) | J6: School Year | N6: =IF(Names!Q5="","",Names!Q5) | V6: Report for the Month of | AG6: JUNE | AY6: 1 | BD6: =MONTH(BD2)
B8: Name of School | C8: =IF(Names!Q8="","",UPPER(Names!Q8)) | AA8: Grade Level | AG8: =IF(Names!Q6="","",Names!Q6) | AI8: Section | AO8: =IF(Names!Q7="","",UPPER(Names!Q7)) | AY8: =MID($N$6,1,1) | AZ8: =MID($N$6,2,1) | BA8: =MID($N$6,3,1) | BB8: =MID($N$6,4,1) | BH8: MALE | BI8: FEMALE
BF9: 1
A10: LEARNER'S NAME (Last Name, First Name, Middle Name) | D10: (1st row for date) | AO10: Total for the Month | AR10: REMARKS (If DROPPED OUT, state reason, please refer to legend number 2. If TRANSFERRED IN/OUT, write the name of School.) | BE10: DROPPED OUT | BF10: 2 | BH10: =COUNTIF($BE$13:$BE$52,"2") | BI10: =COUNTIF($BE$54:$BE$93,"2")
D11: =IF(MONTH($BD$2)<>MONTH($BD$2-(WEEKDAY($BD$2,1)-($AY$6-1))-IF((WEEKDAY($BD$2,1)-($AY$6-1))<=0,7,0)+(ROW(D11)-ROW($D$11))*7+(COLUMN(D11)-COLUMN($D$11)+1)),"",$BD$2-(WEEKDAY($BD$2,1)-($AY$6-1))-IF((WEEKDAY($BD$2,1)-($AY$6-1))<=0,7,0)+(ROW(D11)-ROW($D$11))*7+(COLUMN(D11)-COLUMN($D$11)+1)) | E11: =IFERROR(IF(MONTH($BD$2)<>MONTH($BD$2-(WEEKDAY($BD$2,1)-($AY$6-1))-IF((WEEKDAY($BD$2,1)-($AY$6-1))<=0,7,0)+(ROW(E11)-ROW($D$11))*7+(COLUMN(E11)-COLUMN($D$11)+1)),"",$BD$2-(WEEKDAY($BD$2,1)-($AY$6-1))-IF((WEEKDAY($BD$2,1)-($AY$6-1))<=0,7,0)+(ROW(E11)-ROW($D$11))*7+(COLUMN(E11)-COLUMN($D$11)+1)),"") | F11: =IFERROR(IF(MONTH($BD$2)<>MONTH($BD$2-(WEEKDAY($BD$2,1)-($AY$6-1))-IF((WEEKDAY($BD$2,1)-($AY$6-1))<=0,7,0)+(ROW(F11)-ROW($D$11))*7+(COLUMN(F11)-COLUMN($D$11)+1)),"",$BD$2-(WEEKDAY($BD$2,1)-($AY$6-1))-IF((WEEKDAY($BD$2,1)-($AY$6-1))<=0,7,0)+(ROW(F11)-ROW($D$11))*7+(COLUMN(F11)-COLUMN($D$11)+1)),"") | G11: =IFERROR(IF(MONTH($BD$2)<>MONTH($BD$2-(WEEKDAY($BD$2,1)-($AY$6-1))-IF((WEEKDAY($BD$2,1)-($AY$6-1))<=0,7,0)+(ROW(G11)-ROW($D$11))*7+(COLUMN(G11)-COLUMN($D$11)+1)),"",$BD$2-(WEEKDAY($BD$2,1)-($AY$6-1))-IF((WEEKDAY($BD$2,1)-($AY$6-1))<=0,7,0)+(ROW(G11)-ROW($D$11))*7+(COLUMN(G11)-COLUMN($D$11)+1)),"") | H11: =IFERROR(IF(MONTH($BD$2)<>MONTH($BD$2-(WEEKDAY($BD$2,1)-($AY$6-1))-IF((WEEKDAY($BD$2,1)-($AY$6-1))<=0,7,0)+(ROW(H11)-ROW($D$11))*7+(COLUMN(H11)-COLUMN($D$11)+1)),"",$BD$2-(WEEKDAY($BD$2,1)-($AY$6-1))-IF((WEEKDAY($BD$2,1)-($AY$6-1))<=0,7,0)+(ROW(H11)-ROW($D$11))*7+(COLUMN(H11)-COLUMN($D$11)+1)),"") | I11: =IFERROR(IF(MONTH($BD$2)<>MONTH($BD$2-(WEEKDAY($BD$2,1)-($AY$6-1))-IF((WEEKDAY($BD$2,1)-($AY$6-1))<=0,7,0)+(ROW(I11)-ROW($D$11))*7+(COLUMN(I11)-COLUMN($D$11)+1)),"",$BD$2-(WEEKDAY($BD$2,1)-($AY$6-1))-IF((WEEKDAY($BD$2,1)-($AY$6-1))<=0,7,0)+(ROW(I11)-ROW($D$11))*7+(COLUMN(I11)-COLUMN($D$11)+1)),"") | J11: =IF(MONTH($BD$2)<>MONTH($BD$2-(WEEKDAY($BD$2,1)-($AY$6-1))-IF((WEEKDAY($BD$2,1)-($AY$6-1))<=0,7,0)+(ROW(J11)-ROW($D$11))*7+(COLUMN(J11)-COLUMN($D$11)+1)),"",$BD$2-(WEEKDAY($BD$2,1)-($AY$6-1))-IF((WEEKDAY($BD$2,1)-($AY$6-1))<=0,7,0)+(ROW(J11)-ROW($D$11))*7+(COLUMN(J11)-COLUMN($D$11)+1)) | K11: =IF(MONTH($BD$2)<>MONTH($BD$2-(WEEKDAY($BD$2,1)-($AY$6-1))-IF((WEEKDAY($BD$2,1)-($AY$6-1))<=0,7,0)+(ROW(K11)-ROW($D$11))*7+(COLUMN(K11)-COLUMN($D$11)+1)),"",$BD$2-(WEEKDAY($BD$2,1)-($AY$6-1))-IF((WEEKDAY($BD$2,1)-($AY$6-1))<=0,7,0)+(ROW(K11)-ROW($D$11))*7+(COLUMN(K11)-COLUMN($D$11)+1)) | L11: =IFERROR(IF(MONTH($BD$2)<>MONTH($BD$2-(WEEKDAY($BD$2,1)-($AY$6-1))-IF((WEEKDAY($BD$2,1)-($AY$6-1))<=0,7,0)+(ROW(L11)-ROW($D$11))*7+(COLUMN(L11)-COLUMN($D$11)+1)),"",$BD$2-(WEEKDAY($BD$2,1)-($AY$6-1))-IF((WEEKDAY($BD$2,1)-($AY$6-1))<=0,7,0)+(ROW(L11)-ROW($D$11))*7+(COLUMN(L11)-COLUMN($D$11)+1)),"") | M11: =IFERROR(IF(MONTH($BD$2)<>MONTH($BD$2-(WEEKDAY($BD$2,1)-($AY$6-1))-IF((WEEKDAY($BD$2,1)-($AY$6-1))<=0,7,0)+(ROW(M11)-ROW($D$11))*7+(COLUMN(M11)-COLUMN($D$11)+1)),"",$BD$2-(WEEKDAY($BD$2,1)-($AY$6-1))-IF((WEEKDAY($BD$2,1)-($AY$6-1))<=0,7,0)+(ROW(M11)-ROW($D$11))*7+(COLUMN(M11)-COLUMN($D$11)+1)),"") | N11: =IFERROR(IF(MONTH($BD$2)<>MONTH($BD$2-(WEEKDAY($BD$2,1)-($AY$6-1))-IF((WEEKDAY($BD$2,1)-($AY$6-1))<=0,7,0)+(ROW(N11)-ROW($D$11))*7+(COLUMN(N11)-COLUMN($D$11)+1)),"",$BD$2-(WEEKDAY($BD$2,1)-($AY$6-1))-IF((WEEKDAY($BD$2,1)-($AY$6-1))<=0,7,0)+(ROW(N11)-ROW($D$11))*7+(COLUMN(N11)-COLUMN($D$11)+1)),"") | O11: =IFERROR(IF(MONTH($BD$2)<>MONTH($BD$2-(WEEKDAY($BD$2,1)-($AY$6-1))-IF((WEEKDAY($BD$2,1)-($AY$6-1))<=0,7,0)+(ROW(O11)-ROW($D$11))*7+(COLUMN(O11)-COLUMN($D$11)+1)),"",$BD$2-(WEEKDAY($BD$2,1)-($AY$6-1))-IF((WEEKDAY($BD$2,1)-($AY$6-1))<=0,7,0)+(ROW(O11)-ROW($D$11))*7+(COLUMN(O11)-COLUMN($D$11)+1)),"") | P11: =IFERROR(IF(MONTH($BD$2)<>MONTH($BD$2-(WEEKDAY($BD$2,1)-($AY$6-1))-IF((WEEKDAY($BD$2,1)-($AY$6-1))<=0,7,0)+(ROW(P11)-ROW($D$11))*7+(COLUMN(P11)-COLUMN($D$11)+1)),"",$BD$2-(WEEKDAY($BD$2,1)-($AY$6-1))-IF((WEEKDAY($BD$2,1)-($AY$6-1))<=0,7,0)+(ROW(P11)-ROW($D$11))*7+(COLUMN(P11)-COLUMN($D$11)+1)),"") | Q11: =IF(MONTH($BD$2)<>MONTH($BD$2-(WEEKDAY($BD$2,1)-($AY$6-1))-IF((WEEKDAY($BD$2,1)-($AY$6-1))<=0,7,0)+(ROW(Q11)-ROW($D$11))*7+(COLUMN(Q11)-COLUMN($D$11)+1)),"",$BD$2-(WEEKDAY($BD$2,1)-($AY$6-1))-IF((WEEKDAY($BD$2,1)-($AY$6-1))<=0,7,0)+(ROW(Q11)-ROW($D$11))*7+(COLUMN(Q11)-COLUMN($D$11)+1)) | R11: =IF(MONTH($BD$2)<>MONTH($BD$2-(WEEKDAY($BD$2,1)-($AY$6-1))-IF((WEEKDAY($BD$2,1)-($AY$6-1))<=0,7,0)+(ROW(R11)-ROW($D$11))*7+(COLUMN(R11)-COLUMN($D$11)+1)),"",$BD$2-(WEEKDAY($BD$2,1)-($AY$6-1))-IF((WEEKDAY($BD$2,1)-($AY$6-1))<=0,7,0)+(ROW(R11)-ROW($D$11))*7+(COLUMN(R11)-COLUMN($D$11)+1)) | S11: =IFERROR(IF(MONTH($BD$2)<>MONTH($BD$2-(WEEKDAY($BD$2,1)-($AY$6-1))-IF((WEEKDAY($BD$2,1)-($AY$6-1))<=0,7,0)+(ROW(S11)-ROW($D$11))*7+(COLUMN(S11)-COLUMN($D$11)+1)),"",$BD$2-(WEEKDAY($BD$2,1)-($AY$6-1))-IF((WEEKDAY($BD$2,1)-($AY$6-1))<=0,7,0)+(ROW(S11)-ROW($D$11))*7+(COLUMN(S11)-COLUMN($D$11)+1)),"") | T11: =IFERROR(IF(MONTH($BD$2)<>MONTH($BD$2-(WEEKDAY($BD$2,1)-($AY$6-1))-IF((WEEKDAY($BD$2,1)-($AY$6-1))<=0,7,0)+(ROW(T11)-ROW($D$11))*7+(COLUMN(T11)-COLUMN($D$11)+1)),"",$BD$2-(WEEKDAY($BD$2,1)-($AY$6-1))-IF((WEEKDAY($BD$2,1)-($AY$6-1))<=0,7,0)+(ROW(T11)-ROW($D$11))*7+(COLUMN(T11)-COLUMN($D$11)+1)),"") | U11: =IFERROR(IF(MONTH($BD$2)<>MONTH($BD$2-(WEEKDAY($BD$2,1)-($AY$6-1))-IF((WEEKDAY($BD$2,1)-($AY$6-1))<=0,7,0)+(ROW(U11)-ROW($D$11))*7+(COLUMN(U11)-COLUMN($D$11)+1)),"",$BD$2-(WEEKDAY($BD$2,1)-($AY$6-1))-IF((WEEKDAY($BD$2,1)-($AY$6-1))<=0,7,0)+(ROW(U11)-ROW($D$11))*7+(COLUMN(U11)-COLUMN($D$11)+1)),"") | V11: =IFERROR(IF(MONTH($BD$2)<>MONTH($BD$2-(WEEKDAY($BD$2,1)-($AY$6-1))-IF((WEEKDAY($BD$2,1)-($AY$6-1))<=0,7,0)+(ROW(V11)-ROW($D$11))*7+(COLUMN(V11)-COLUMN($D$11)+1)),"",$BD$2-(WEEKDAY($BD$2,1)-($AY$6-1))-IF((WEEKDAY($BD$2,1)-($AY$6-1))<=0,7,0)+(ROW(V11)-ROW($D$11))*7+(COLUMN(V11)-COLUMN($D$11)+1)),"") | W11: =IFERROR(IF(MONTH($BD$2)<>MONTH($BD$2-(WEEKDAY($BD$2,1)-($AY$6-1))-IF((WEEKDAY($BD$2,1)-($AY$6-1))<=0,7,0)+(ROW(W11)-ROW($D$11))*7+(COLUMN(W11)-COLUMN($D$11)+1)),"",$BD$2-(WEEKDAY($BD$2,1)-($AY$6-1))-IF((WEEKDAY($BD$2,1)-($AY$6-1))<=0,7,0)+(ROW(W11)-ROW($D$11))*7+(COLUMN(W11)-COLUMN($D$11)+1)),"") | X11: =IF(MONTH($BD$2)<>MONTH($BD$2-(WEEKDAY($BD$2,1)-($AY$6-1))-IF((WEEKDAY($BD$2,1)-($AY$6-1))<=0,7,0)+(ROW(X11)-ROW($D$11))*7+(COLUMN(X11)-COLUMN($D$11)+1)),"",$BD$2-(WEEKDAY($BD$2,1)-($AY$6-1))-IF((WEEKDAY($BD$2,1)-($AY$6-1))<=0,7,0)+(ROW(X11)-ROW($D$11))*7+(COLUMN(X11)-COLUMN($D$11)+1)) | Y11: =IF(MONTH($BD$2)<>MONTH($BD$2-(WEEKDAY($BD$2,1)-($AY$6-1))-IF((WEEKDAY($BD$2,1)-($AY$6-1))<=0,7,0)+(ROW(Y11)-ROW($D$11))*7+(COLUMN(Y11)-COLUMN($D$11)+1)),"",$BD$2-(WEEKDAY($BD$2,1)-($AY$6-1))-IF((WEEKDAY($BD$2,1)-($AY$6-1))<=0,7,0)+(ROW(Y11)-ROW($D$11))*7+(COLUMN(Y11)-COLUMN($D$11)+1)) | Z11: =IFERROR(IF(MONTH($BD$2)<>MONTH($BD$2-(WEEKDAY($BD$2,1)-($AY$6-1))-IF((WEEKDAY($BD$2,1)-($AY$6-1))<=0,7,0)+(ROW(Z11)-ROW($D$11))*7+(COLUMN(Z11)-COLUMN($D$11)+1)),"",$BD$2-(WEEKDAY($BD$2,1)-($AY$6-1))-IF((WEEKDAY($BD$2,1)-($AY$6-1))<=0,7,0)+(ROW(Z11)-ROW($D$11))*7+(COLUMN(Z11)-COLUMN($D$11)+1)),"") | AA11: =IFERROR(IF(MONTH($BD$2)<>MONTH($BD$2-(WEEKDAY($BD$2,1)-($AY$6-1))-IF((WEEKDAY($BD$2,1)-($AY$6-1))<=0,7,0)+(ROW(AA11)-ROW($D$11))*7+(COLUMN(AA11)-COLUMN($D$11)+1)),"",$BD$2-(WEEKDAY($BD$2,1)-($AY$6-1))-IF((WEEKDAY($BD$2,1)-($AY$6-1))<=0,7,0)+(ROW(AA11)-ROW($D$11))*7+(COLUMN(AA11)-COLUMN($D$11)+1)),"") | AB11: =IFERROR(IF(MONTH($BD$2)<>MONTH($BD$2-(WEEKDAY($BD$2,1)-($AY$6-1))-IF((WEEKDAY($BD$2,1)-($AY$6-1))<=0,7,0)+(ROW(AB11)-ROW($D$11))*7+(COLUMN(AB11)-COLUMN($D$11)+1)),"",$BD$2-(WEEKDAY($BD$2,1)-($AY$6-1))-IF((WEEKDAY($BD$2,1)-($AY$6-1))<=0,7,0)+(ROW(AB11)-ROW($D$11))*7+(COLUMN(AB11)-COLUMN($D$11)+1)),"") | AC11: =IFERROR(IF(MONTH($BD$2)<>MONTH($BD$2-(WEEKDAY($BD$2,1)-($AY$6-1))-IF((WEEKDAY($BD$2,1)-($AY$6-1))<=0,7,0)+(ROW(AC11)-ROW($D$11))*7+(COLUMN(AC11)-COLUMN($D$11)+1)),"",$BD$2-(WEEKDAY($BD$2,1)-($AY$6-1))-IF((WEEKDAY($BD$2,1)-($AY$6-1))<=0,7,0)+(ROW(AC11)-ROW($D$11))*7+(COLUMN(AC11)-COLUMN($D$11)+1)),"") | AD11: =IFERROR(IF(MONTH($BD$2)<>MONTH($BD$2-(WEEKDAY($BD$2,1)-($AY$6-1))-IF((WEEKDAY($BD$2,1)-($AY$6-1))<=0,7,0)+(ROW(AD11)-ROW($D$11))*7+(COLUMN(AD11)-COLUMN($D$11)+1)),"",$BD$2-(WEEKDAY($BD$2,1)-($AY$6-1))-IF((WEEKDAY($BD$2,1)-($AY$6-1))<=0,7,0)+(ROW(AD11)-ROW($D$11))*7+(COLUMN(AD11)-COLUMN($D$11)+1)),"") | AE11: =IF(MONTH($BD$2)<>MONTH($BD$2-(WEEKDAY($BD$2,1)-($AY$6-1))-IF((WEEKDAY($BD$2,1)-($AY$6-1))<=0,7,0)+(ROW(AE11)-ROW($D$11))*7+(COLUMN(AE11)-COLUMN($D$11)+1)),"",$BD$2-(WEEKDAY($BD$2,1)-($AY$6-1))-IF((WEEKDAY($BD$2,1)-($AY$6-1))<=0,7,0)+(ROW(AE11)-ROW($D$11))*7+(COLUMN(AE11)-COLUMN($D$11)+1)) | AF11: =IF(MONTH($BD$2)<>MONTH($BD$2-(WEEKDAY($BD$2,1)-($AY$6-1))-IF((WEEKDAY($BD$2,1)-($AY$6-1))<=0,7,0)+(ROW(AF11)-ROW($D$11))*7+(COLUMN(AF11)-COLUMN($D$11)+1)),"",$BD$2-(WEEKDAY($BD$2,1)-($AY$6-1))-IF((WEEKDAY($BD$2,1)-($AY$6-1))<=0,7,0)+(ROW(AF11)-ROW($D$11))*7+(COLUMN(AF11)-COLUMN($D$11)+1)) | AG11: =IFERROR(IF(MONTH($BD$2)<>MONTH($BD$2-(WEEKDAY($BD$2,1)-($AY$6-1))-IF((WEEKDAY($BD$2,1)-($AY$6-1))<=0,7,0)+(ROW(AG11)-ROW($D$11))*7+(COLUMN(AG11)-COLUMN($D$11)+1)),"",$BD$2-(WEEKDAY($BD$2,1)-($AY$6-1))-IF((WEEKDAY($BD$2,1)-($AY$6-1))<=0,7,0)+(ROW(AG11)-ROW($D$11))*7+(COLUMN(AG11)-COLUMN($D$11)+1)),"") | AH11: =IFERROR(IF(MONTH($BD$2)<>MONTH($BD$2-(WEEKDAY($BD$2,1)-($AY$6-1))-IF((WEEKDAY($BD$2,1)-($AY$6-1))<=0,7,0)+(ROW(AH11)-ROW($D$11))*7+(COLUMN(AH11)-COLUMN($D$11)+1)),"",$BD$2-(WEEKDAY($BD$2,1)-($AY$6-1))-IF((WEEKDAY($BD$2,1)-($AY$6-1))<=0,7,0)+(ROW(AH11)-ROW($D$11))*7+(COLUMN(AH11)-COLUMN($D$11)+1)),"") | AI11: =IFERROR(IF(MONTH($BD$2)<>MONTH($BD$2-(WEEKDAY($BD$2,1)-($AY$6-1))-IF((WEEKDAY($BD$2,1)-($AY$6-1))<=0,7,0)+(ROW(AI11)-ROW($D$11))*7+(COLUMN(AI11)-COLUMN($D$11)+1)),"",$BD$2-(WEEKDAY($BD$2,1)-($AY$6-1))-IF((WEEKDAY($BD$2,1)-($AY$6-1))<=0,7,0)+(ROW(AI11)-ROW($D$11))*7+(COLUMN(AI11)-COLUMN($D$11)+1)),"") | AJ11: =IFERROR(IF(MONTH($BD$2)<>MONTH($BD$2-(WEEKDAY($BD$2,1)-($AY$6-1))-IF((WEEKDAY($BD$2,1)-($AY$6-1))<=0,7,0)+(ROW(AJ11)-ROW($D$11))*7+(COLUMN(AJ11)-COLUMN($D$11)+1)),"",$BD$2-(WEEKDAY($BD$2,1)-($AY$6-1))-IF((WEEKDAY($BD$2,1)-($AY$6-1))<=0,7,0)+(ROW(AJ11)-ROW($D$11))*7+(COLUMN(AJ11)-COLUMN($D$11)+1)),"") | AK11: =IFERROR(IF(MONTH($BD$2)<>MONTH($BD$2-(WEEKDAY($BD$2,1)-($AY$6-1))-IF((WEEKDAY($BD$2,1)-($AY$6-1))<=0,7,0)+(ROW(AK11)-ROW($D$11))*7+(COLUMN(AK11)-COLUMN($D$11)+1)),"",$BD$2-(WEEKDAY($BD$2,1)-($AY$6-1))-IF((WEEKDAY($BD$2,1)-($AY$6-1))<=0,7,0)+(ROW(AK11)-ROW($D$11))*7+(COLUMN(AK11)-COLUMN($D$11)+1)),"") | AL11: =IF(MONTH($BD$2)<>MONTH($BD$2-(WEEKDAY($BD$2,1)-($AY$6-1))-IF((WEEKDAY($BD$2,1)-($AY$6-1))<=0,7,0)+(ROW(AL11)-ROW($D$11))*7+(COLUMN(AL11)-COLUMN($D$11)+1)),"",$BD$2-(WEEKDAY($BD$2,1)-($AY$6-1))-IF((WEEKDAY($BD$2,1)-($AY$6-1))<=0,7,0)+(ROW(AL11)-ROW($D$11))*7+(COLUMN(AL11)-COLUMN($D$11)+1)) | AM11: =IF(MONTH($BD$2)<>MONTH($BD$2-(WEEKDAY($BD$2,1)-($AY$6-1))-IF((WEEKDAY($BD$2,1)-($AY$6-1))<=0,7,0)+(ROW(AM11)-ROW($D$11))*7+(COLUMN(AM11)-COLUMN($D$11)+1)),"",$BD$2-(WEEKDAY($BD$2,1)-($AY$6-1))-IF((WEEKDAY($BD$2,1)-($AY$6-1))<=0,7,0)+(ROW(AM11)-ROW($D$11))*7+(COLUMN(AM11)-COLUMN($D$11)+1)) | AN11: =IFERROR(IF(MONTH($BD$2)<>MONTH($BD$2-(WEEKDAY($BD$2,1)-($AY$6-1))-IF((WEEKDAY($BD$2,1)-($AY$6-1))<=0,7,0)+(ROW(AN11)-ROW($D$11))*7+(COLUMN(AN11)-COLUMN($D$11)+1)),"",$BD$2-(WEEKDAY($BD$2,1)-($AY$6-1))-IF((WEEKDAY($BD$2,1)-($AY$6-1))<=0,7,0)+(ROW(AN11)-ROW($D$11))*7+(COLUMN(AN11)-COLUMN($D$11)+1)),"") | BE11: TRANSFERRED OUT | BF11: 3 | BH11: =COUNTIF($BE$13:$BE$52,"3") | BI11: =COUNTIF($BE$54:$BE$93,"3")
D12: S | E12: M | F12: T | G12: W | H12: TH | I12: F | J12: SAT | K12: S | L12: M | M12: T | N12: W | O12: TH | P12: F | Q12: SAT | R12: S | S12: M | T12: T | U12: W | V12: TH | W12: F | X12: SAT | Y12: S | Z12: M | AA12: T | AB12: W | AC12: TH | AD12: F | AE12: SAT | AF12: S | AG12: M | AH12: T | AI12: W | AJ12: TH | AK12: F | AL12: SAT | AM12: S | AN12: M | AO12: ABSENT | AP12: TARDY | AQ12: PRES | BB12: HOLIDAYS | BE12: TRANSFERRED IN | BF12: 4 | BH12: =COUNTIF($BE$13:$BE$52,"4") | BI12: =COUNTIF($BE$54:$BE$93,"4")
A13: =IF(B13="","",1) | B13: =IF(Names!B5="","",Names!B5) | AO13: =AO135 | AP13: =IF(B13="","",AO227) | AQ13: =IFERROR($AT$97-AO13,"") | AX13: =IF(AR13="","",VLOOKUP(AR13,$BE$9:$BF$12,2,0)) | AY13: JANUARY | AZ13: 1 | BA13: =$AZ$3+1 | BB13: =IF(BC13=$AG$6,BD13,0) | BC13: =Holidays!B6 | BD13: =Holidays!C6 | BE13: =IF(B13="","",AX13) | BF13: 1. CODES FOR CHECKING ATTENDANCE
A14: =IF(B14="","",A13+1) | B14: =IF(Names!B6="","",Names!B6) | AO14: =AO136 | AP14: =IF(B14="","",AO228) | AQ14: =IFERROR($AT$97-AO14,"") | AX14: =IF(AR14="","",VLOOKUP(AR14,$BE$9:$BF$12,2,0)) | AY14: FEBRUARY | AZ14: 2 | BA14: =$AZ$3+1 | BB14: =IF(BC14=$AG$6,BD14,0) | BC14: =Holidays!B7 | BD14: =Holidays!C7 | BE14: =IF(B14="","",AX14) | BF14: (blank) - Present; (x)- Absent; Tardy (T)
A15: =IF(B15="","",A14+1) | B15: =IF(Names!B7="","",Names!B7) | AO15: =AO137 | AP15: =IF(B15="","",AO229) | AQ15: =IFERROR($AT$97-AO15,"") | AX15: =IF(AR15="","",VLOOKUP(AR15,$BE$9:$BF$12,2,0)) | AY15: MARCH | AZ15: 3 | BA15: =$AZ$3+1 | BB15: =IF(BC15=$AG$6,BD15,0) | BC15: =Holidays!B8 | BD15: =Holidays!C8 | BE15: =IF(B15="","",AX15)
A16: =IF(B16="","",A15+1) | B16: =IF(Names!B8="","",Names!B8) | AO16: =AO138 | AP16: =IF(B16="","",AO230) | AQ16: =IFERROR($AT$97-AO16,"") | AX16: =IF(AR16="","",VLOOKUP(AR16,$BE$9:$BF$12,2,0)) | AY16: APRIL | AZ16: 4 | BA16: =$AZ$3+1 | BB16: =IF(BC16=$AG$6,BD16,0) | BC16: =Holidays!B9 | BD16: =Holidays!C9 | BE16: =IF(B16="","",AX16) | BF16: 2. REASONS/CAUSES FOR DROPPING OUT
A17: =IF(B17="","",A16+1) | B17: =IF(Names!B9="","",Names!B9) | AO17: =AO139 | AP17: =IF(B17="","",AO231) | AQ17: =IFERROR($AT$97-AO17,"") | AX17: =IF(AR17="","",VLOOKUP(AR17,$BE$9:$BF$12,2,0)) | AY17: MAY | AZ17: 5 | BA17: =$AZ$3+1 | BB17: =IF(BC17=$AG$6,BD17,0) | BC17: =Holidays!B10 | BD17: =Holidays!C10 | BE17: =IF(B17="","",AX17) | BF17: a. Domestic-Related Factors | BH17: a.1. Had to take care of siblings
A18: =IF(B18="","",A17+1) | B18: =IF(Names!B10="","",Names!B10) | AO18: =AO140 | AP18: =IF(B18="","",AO232) | AQ18: =IFERROR($AT$97-AO18,"") | AX18: =IF(AR18="","",VLOOKUP(AR18,$BE$9:$BF$12,2,0)) | AY18: JUNE | AZ18: 6 | BA18: =$AZ$3 | BB18: =IF(BC18=$AG$6,BD18,0) | BC18: =Holidays!B11 | BD18: =Holidays!C11 | BE18: =IF(B18="","",AX18) | BH18: a.2. Early marriage/pregnancy
A19: =IF(B19="","",A18+1) | B19: =IF(Names!B11="","",Names!B11) | AO19: =AO141 | AP19: =IF(B19="","",AO233) | AQ19: =IFERROR($AT$97-AO19,"") | AX19: =IF(AR19="","",VLOOKUP(AR19,$BE$9:$BF$12,2,0)) | AY19: JULY | AZ19: 7 | BA19: =$AZ$3 | BB19: =IF(BC19=$AG$6,BD19,0) | BC19: =Holidays!B12 | BD19: =Holidays!C12 | BE19: =IF(B19="","",AX19) | BH19: a.3. Parents' attitude toward schooling
A20: =IF(B20="","",A19+1) | B20: =IF(Names!B12="","",Names!B12) | AO20: =AO142 | AP20: =IF(B20="","",AO234) | AQ20: =IFERROR($AT$97-AO20,"") | AX20: =IF(AR20="","",VLOOKUP(AR20,$BE$9:$BF$12,2,0)) | AY20: AUGUST | AZ20: 8 | BA20: =$AZ$3 | BB20: =IF(BC20=$AG$6,BD20,0) | BC20: =Holidays!B13 | BD20: =Holidays!C13 | BE20: =IF(B20="","",AX20) | BH20: a.4. Family problems
A21: =IF(B21="","",A20+1) | B21: =IF(Names!B13="","",Names!B13) | AO21: =AO143 | AP21: =IF(B21="","",AO235) | AQ21: =IFERROR($AT$97-AO21,"") | AX21: =IF(AR21="","",VLOOKUP(AR21,$BE$9:$BF$12,2,0)) | AY21: SEPTEMBER | AZ21: 9 | BA21: =$AZ$3 | BB21: =IF(BC21=$AG$6,BD21,0) | BC21: =Holidays!B14 | BD21: =Holidays!C14 | BE21: =IF(B21="","",AX21) | BF21: b. Individual-Related Factors | BH21: b.1. Illness
A22: =IF(B22="","",A21+1) | B22: =IF(Names!B14="","",Names!B14) | AO22: =AO144 | AP22: =IF(B22="","",AO236) | AQ22: =IFERROR($AT$97-AO22,"") | AX22: =IF(AR22="","",VLOOKUP(AR22,$BE$9:$BF$12,2,0)) | AY22: OCTOBER | AZ22: 10 | BA22: =$AZ$3 | BB22: =IF(BC22=$AG$6,BD22,0) | BC22: =Holidays!B15 | BD22: =Holidays!C15 | BE22: =IF(B22="","",AX22) | BH22: b.2. Overage
A23: =IF(B23="","",A22+1) | B23: =IF(Names!B15="","",Names!B15) | AO23: =AO145 | AP23: =IF(B23="","",AO237) | AQ23: =IFERROR($AT$97-AO23,"") | AX23: =IF(AR23="","",VLOOKUP(AR23,$BE$9:$BF$12,2,0)) | AY23: NOVEMBER | AZ23: 11 | BA23: =$AZ$3 | BB23: =IF(BC23=$AG$6,BD23,0) | BC23: =Holidays!B16 | BD23: =Holidays!C16 | BE23: =IF(B23="","",AX23) | BH23: b.3. Death
A24: =IF(B24="","",A23+1) | B24: =IF(Names!B16="","",Names!B16) | AO24: =AO146 | AP24: =IF(B24="","",AO238) | AQ24: =IFERROR($AT$97-AO24,"") | AX24: =IF(AR24="","",VLOOKUP(AR24,$BE$9:$BF$12,2,0)) | AY24: DECEMBER | AZ24: 12 | BA24: =$AZ$3 | BB24: =IF(BC24=$AG$6,BD24,0) | BC24: =Holidays!B17 | BD24: =Holidays!C17 | BE24: =IF(B24="","",AX24) | BH24: b.4. Drug Abuse
A25: =IF(B25="","",A24+1) | B25: =IF(Names!B17="","",Names!B17) | AO25: =AO147 | AP25: =IF(B25="","",AO239) | AQ25: =IFERROR($AT$97-AO25,"") | AX25: =IF(AR25="","",VLOOKUP(AR25,$BE$9:$BF$12,2,0)) | AZ25: 13 | BB25: =IF(BC25=$AG$6,BD25,0) | BC25: =Holidays!B18 | BD25: =Holidays!C18 | BE25: =IF(B25="","",AX25) | BH25: b.5. Poor academic performance
A26: =IF(B26="","",A25+1) | B26: =IF(Names!B18="","",Names!B18) | AO26: =AO148 | AP26: =IF(B26="","",AO240) | AQ26: =IFERROR($AT$97-AO26,"") | AX26: =IF(AR26="","",VLOOKUP(AR26,$BE$9:$BF$12,2,0)) | BB26: =IF(BC26=$AG$6,BD26,0) | BC26: =Holidays!B19 | BD26: =Holidays!C19 | BE26: =IF(B26="","",AX26) | BH26: b.6. Lack of interest/Distractions
A27: =IF(B27="","",A26+1) | B27: =IF(Names!B19="","",Names!B19) | AO27: =AO149 | AP27: =IF(B27="","",AO241) | AQ27: =IFERROR($AT$97-AO27,"") | AX27: =IF(AR27="","",VLOOKUP(AR27,$BE$9:$BF$12,2,0)) | BB27: =IF(BC27=$AG$6,BD27,0) | BC27: =Holidays!B20 | BD27: =Holidays!C20 | BE27: =IF(B27="","",AX27) | BH27: b.7. Hunger/Malnutrition
A28: =IF(B28="","",A27+1) | B28: =IF(Names!B20="","",Names!B20) | AO28: =AO150 | AP28: =IF(B28="","",AO242) | AQ28: =IFERROR($AT$97-AO28,"") | AX28: =IF(AR28="","",VLOOKUP(AR28,$BE$9:$BF$12,2,0)) | BB28: =IF(BC28=$AG$6,BD28,0) | BC28: =Holidays!B21 | BD28: =Holidays!C21 | BE28: =IF(B28="","",AX28) | BF28: c. School-Related Factors | BH28: c.1. Teacher Factor
A29: =IF(B29="","",A28+1) | B29: =IF(Names!B21="","",Names!B21) | AO29: =AO151 | AP29: =IF(B29="","",AO243) | AQ29: =IFERROR($AT$97-AO29,"") | AX29: =IF(AR29="","",VLOOKUP(AR29,$BE$9:$BF$12,2,0)) | BB29: =IF(BC29=$AG$6,BD29,0) | BC29: =Holidays!B22 | BD29: =Holidays!C22 | BE29: =IF(B29="","",AX29) | BH29: c.2. Physical condition of classroom
A30: =IF(B30="","",A29+1) | B30: =IF(Names!B22="","",Names!B22) | AO30: =AO152 | AP30: =IF(B30="","",AO244) | AQ30: =IFERROR($AT$97-AO30,"") | AX30: =IF(AR30="","",VLOOKUP(AR30,$BE$9:$BF$12,2,0)) | BB30: =IF(BC30=$AG$6,BD30,0) | BC30: =Holidays!B23 | BD30: =Holidays!C23 | BE30: =IF(B30="","",AX30) | BH30: c.3. Peer influence
A31: =IF(B31="","",A30+1) | B31: =IF(Names!B23="","",Names!B23) | AO31: =AO153 | AP31: =IF(B31="","",AO245) | AQ31: =IFERROR($AT$97-AO31,"") | AX31: =IF(AR31="","",VLOOKUP(AR31,$BE$9:$BF$12,2,0)) | BB31: =IF(BC31=$AG$6,BD31,0) | BC31: =Holidays!B24 | BD31: =Holidays!C24 | BE31: =IF(B31="","",AX31) | BF31: d. Geographic/Environmental | BH31: d.1. Distance between home and school
A32: =IF(B32="","",A31+1) | B32: =IF(Names!B24="","",Names!B24) | AO32: =AO154 | AP32: =IF(B32="","",AO246) | AQ32: =IFERROR($AT$97-AO32,"") | AX32: =IF(AR32="","",VLOOKUP(AR32,$BE$9:$BF$12,2,0)) | BB32: =IF(BC32=$AG$6,BD32,0) | BC32: =Holidays!B25 | BD32: =Holidays!C25 | BE32: =IF(B32="","",AX32) | BH32: d.2. Armed conflict (incl. Tribal wars & clanfeuds)
A33: =IF(B33="","",A32+1) | B33: =IF(Names!B25="","",Names!B25) | AO33: =AO155 | AP33: =IF(B33="","",AO247) | AQ33: =IFERROR($AT$97-AO33,"") | AX33: =IF(AR33="","",VLOOKUP(AR33,$BE$9:$BF$12,2,0)) | BB33: =IF(BC33=$AG$6,BD33,0) | BC33: =Holidays!B26 | BD33: =Holidays!C26 | BE33: =IF(B33="","",AX33) | BH33: d.3. Calamities/Disasters
A34: =IF(B34="","",A33+1) | B34: =IF(Names!B26="","",Names!B26) | AO34: =AO156 | AP34: =IF(B34="","",AO248) | AQ34: =IFERROR($AT$97-AO34,"") | AX34: =IF(AR34="","",VLOOKUP(AR34,$BE$9:$BF$12,2,0)) | BB34: =IF(BC34=$AG$6,BD34,0) | BC34: =Holidays!B27 | BD34: =Holidays!C27 | BE34: =IF(B34="","",AX34) | BF34: e. Financial-Related | BH34: e.1. Child labor, work
A35: =IF(B35="","",A34+1) | B35: =IF(Names!B27="","",Names!B27) | AO35: =AO157 | AP35: =IF(B35="","",AO249) | AQ35: =IFERROR($AT$97-AO35,"") | AX35: =IF(AR35="","",VLOOKUP(AR35,$BE$9:$BF$12,2,0)) | BB35: =IF(BC35=$AG$6,BD35,0) | BC35: =Holidays!B28 | BD35: =Holidays!C28 | BE35: =IF(B35="","",AX35) | BF35: f. Others (Specify) | BH35: =CONCATENATE("f."," ",BH36)
A36: =IF(B36="","",A35+1) | B36: =IF(Names!B28="","",Names!B28) | AO36: =AO158 | AP36: =IF(B36="","",AO250) | AQ36: =IFERROR($AT$97-AO36,"") | AX36: =IF(AR36="","",VLOOKUP(AR36,$BE$9:$BF$12,2,0)) | BB36: =IF(BC36=$AG$6,BD36,0) | BC36: =Holidays!B29 | BD36: =Holidays!C29 | BE36: =IF(B36="","",AX36)
A37: =IF(B37="","",A36+1) | B37: =IF(Names!B29="","",Names!B29) | AO37: =AO159 | AP37: =IF(B37="","",AO251) | AQ37: =IFERROR($AT$97-AO37,"") | AX37: =IF(AR37="","",VLOOKUP(AR37,$BE$9:$BF$12,2,0)) | BB37: =IF(BC37=$AG$6,BD37,0) | BC37: =Holidays!B30 | BD37: =Holidays!C30 | BE37: =IF(B37="","",AX37)
A38: =IF(B38="","",A37+1) | B38: =IF(Names!B30="","",Names!B30) | AO38: =AO160 | AP38: =IF(B38="","",AO252) | AQ38: =IFERROR($AT$97-AO38,"") | AX38: =IF(AR38="","",VLOOKUP(AR38,$BE$9:$BF$12,2,0)) | BB38: =IF(BC38=$AG$6,BD38,0) | BC38: =Holidays!B31 | BD38: =Holidays!C31 | BE38: =IF(B38="","",AX38)
A39: =IF(B39="","",A38+1) | B39: =IF(Names!B31="","",Names!B31) | AO39: =AO161 | AP39: =IF(B39="","",AO253) | AQ39: =IFERROR($AT$97-AO39,"") | AX39: =IF(AR39="","",VLOOKUP(AR39,$BE$9:$BF$12,2,0)) | BB39: =IF(BC39=$AG$6,BD39,0) | BC39: =Holidays!B32 | BD39: =Holidays!C32 | BE39: =IF(B39="","",AX39)
A40: =IF(B40="","",A39+1) | B40: =IF(Names!B32="","",Names!B32) | AO40: =AO162 | AP40: =IF(B40="","",AO254) | AQ40: =IFERROR($AT$97-AO40,"") | AX40: =IF(AR40="","",VLOOKUP(AR40,$BE$9:$BF$12,2,0)) | BB40: =IF(BC40=$AG$6,BD40,0) | BC40: =Holidays!B33 | BD40: =Holidays!C33 | BE40: =IF(B40="","",AX40)
A41: =IF(B41="","",A40+1) | B41: =IF(Names!B33="","",Names!B33) | AO41: =AO163 | AP41: =IF(B41="","",AO255) | AQ41: =IFERROR($AT$97-AO41,"") | AX41: =IF(AR41="","",VLOOKUP(AR41,$BE$9:$BF$12,2,0)) | BB41: =IF(BC41=$AG$6,BD41,0) | BC41: =Holidays!B34 | BD41: =Holidays!C34 | BE41: =IF(B41="","",AX41)
A42: =IF(B42="","",A41+1) | B42: =IF(Names!B34="","",Names!B34) | AO42: =AO164 | AP42: =IF(B42="","",AO256) | AQ42: =IFERROR($AT$97-AO42,"") | AX42: =IF(AR42="","",VLOOKUP(AR42,$BE$9:$BF$12,2,0)) | BB42: =IF(BC42=$AG$6,BD42,0) | BC42: =Holidays!B35 | BD42: =Holidays!C35 | BE42: =IF(B42="","",AX42)
A43: =IF(B43="","",A42+1) | B43: =IF(Names!B35="","",Names!B35) | AO43: =AO165 | AP43: =IF(B43="","",AO257) | AQ43: =IFERROR($AT$97-AO43,"") | AX43: =IF(AR43="","",VLOOKUP(AR43,$BE$9:$BF$12,2,0)) | BB43: =IF(BC43=$AG$6,BD43,0) | BC43: =Holidays!B36 | BD43: =Holidays!C36 | BE43: =IF(B43="","",AX43)
A44: =IF(B44="","",A43+1) | B44: =IF(Names!B36="","",Names!B36) | AO44: =AO166 | AP44: =IF(B44="","",AO258) | AQ44: =IFERROR($AT$97-AO44,"") | AX44: =IF(AR44="","",VLOOKUP(AR44,$BE$9:$BF$12,2,0)) | BB44: =IF(BC44=$AG$6,BD44,0) | BC44: =Holidays!B37 | BD44: =Holidays!C37 | BE44: =IF(B44="","",AX44)
...

Sheet SF2 (JUL)
A2: School Form 2 (SF2) Daily Attendance Report of Learners | AX2: MONTH | AY2: =IF(AG6="","",VLOOKUP(AG6,AX13:AY25,2,0)) | AZ2: YEAR | BA2: =VLOOKUP(AY2,AY13:AZ24,2,0) | BB2: DATE | BC2: =DATE(BA2,AY2,1)
A3: (This replaces Form 1, Form 2 & STS Form 4 - Absenteeism and Dropout Profile) | AX3: YEAR | AY3: =CONCATENATE(AX8,AY8,AZ8,BA8)
B6: School ID | C6: =IF(Names!Q4="","",Names!Q4) | J6: School Year | N6: =IF(Names!Q5="","",Names!Q5) | V6: Report for the Month of | AG6: JULY | AX6: 1 | BC6: =MONTH(BC2)
B8: Name of School | C8: =IF(Names!Q8="","",UPPER(Names!Q8)) | AA8: Grade Level | AG8: =IF(Names!Q6="","",Names!Q6) | AI8: Section | AO8: =IF(Names!Q7="","",UPPER(Names!Q7)) | AX8: =MID($N$6,1,1) | AY8: =MID($N$6,2,1) | AZ8: =MID($N$6,3,1) | BA8: =MID($N$6,4,1) | BG8: MALE | BH8: FEMALE
BE9: 1
A10: LEARNER'S NAME (Last Name, First Name, Middle Name) | D10: (1st row for date) | AO10: Total for the Month | AQ10: REMARKS (If DROPPED OUT, state reason, please refer to legend number 2. If TRANSFERRED IN/OUT, write the name of School.) | BD10: DROPPED OUT | BE10: 2 | BG10: =COUNTIF($BD$13:$BD$52,"2") | BH10: =COUNTIF($BD$54:$BD$93,"2")
D11: =IF(MONTH($BC$2)<>MONTH($BC$2-(WEEKDAY($BC$2,1)-($AX$6-1))-IF((WEEKDAY($BC$2,1)-($AX$6-1))<=0,7,0)+(ROW(D11)-ROW($D$11))*7+(COLUMN(D11)-COLUMN($D$11)+1)),"",$BC$2-(WEEKDAY($BC$2,1)-($AX$6-1))-IF((WEEKDAY($BC$2,1)-($AX$6-1))<=0,7,0)+(ROW(D11)-ROW($D$11))*7+(COLUMN(D11)-COLUMN($D$11)+1)) | E11: =IFERROR(IF(MONTH($BC$2)<>MONTH($BC$2-(WEEKDAY($BC$2,1)-($AX$6-1))-IF((WEEKDAY($BC$2,1)-($AX$6-1))<=0,7,0)+(ROW(E11)-ROW($D$11))*7+(COLUMN(E11)-COLUMN($D$11)+1)),"",$BC$2-(WEEKDAY($BC$2,1)-($AX$6-1))-IF((WEEKDAY($BC$2,1)-($AX$6-1))<=0,7,0)+(ROW(E11)-ROW($D$11))*7+(COLUMN(E11)-COLUMN($D$11)+1)),"") | F11: =IFERROR(IF(MONTH($BC$2)<>MONTH($BC$2-(WEEKDAY($BC$2,1)-($AX$6-1))-IF((WEEKDAY($BC$2,1)-($AX$6-1))<=0,7,0)+(ROW(F11)-ROW($D$11))*7+(COLUMN(F11)-COLUMN($D$11)+1)),"",$BC$2-(WEEKDAY($BC$2,1)-($AX$6-1))-IF((WEEKDAY($BC$2,1)-($AX$6-1))<=0,7,0)+(ROW(F11)-ROW($D$11))*7+(COLUMN(F11)-COLUMN($D$11)+1)),"") | G11: =IFERROR(IF(MONTH($BC$2)<>MONTH($BC$2-(WEEKDAY($BC$2,1)-($AX$6-1))-IF((WEEKDAY($BC$2,1)-($AX$6-1))<=0,7,0)+(ROW(G11)-ROW($D$11))*7+(COLUMN(G11)-COLUMN($D$11)+1)),"",$BC$2-(WEEKDAY($BC$2,1)-($AX$6-1))-IF((WEEKDAY($BC$2,1)-($AX$6-1))<=0,7,0)+(ROW(G11)-ROW($D$11))*7+(COLUMN(G11)-COLUMN($D$11)+1)),"") | H11: =IFERROR(IF(MONTH($BC$2)<>MONTH($BC$2-(WEEKDAY($BC$2,1)-($AX$6-1))-IF((WEEKDAY($BC$2,1)-($AX$6-1))<=0,7,0)+(ROW(H11)-ROW($D$11))*7+(COLUMN(H11)-COLUMN($D$11)+1)),"",$BC$2-(WEEKDAY($BC$2,1)-($AX$6-1))-IF((WEEKDAY($BC$2,1)-($AX$6-1))<=0,7,0)+(ROW(H11)-ROW($D$11))*7+(COLUMN(H11)-COLUMN($D$11)+1)),"") | I11: =IFERROR(IF(MONTH($BC$2)<>MONTH($BC$2-(WEEKDAY($BC$2,1)-($AX$6-1))-IF((WEEKDAY($BC$2,1)-($AX$6-1))<=0,7,0)+(ROW(I11)-ROW($D$11))*7+(COLUMN(I11)-COLUMN($D$11)+1)),"",$BC$2-(WEEKDAY($BC$2,1)-($AX$6-1))-IF((WEEKDAY($BC$2,1)-($AX$6-1))<=0,7,0)+(ROW(I11)-ROW($D$11))*7+(COLUMN(I11)-COLUMN($D$11)+1)),"") | J11: =IF(MONTH($BC$2)<>MONTH($BC$2-(WEEKDAY($BC$2,1)-($AX$6-1))-IF((WEEKDAY($BC$2,1)-($AX$6-1))<=0,7,0)+(ROW(J11)-ROW($D$11))*7+(COLUMN(J11)-COLUMN($D$11)+1)),"",$BC$2-(WEEKDAY($BC$2,1)-($AX$6-1))-IF((WEEKDAY($BC$2,1)-($AX$6-1))<=0,7,0)+(ROW(J11)-ROW($D$11))*7+(COLUMN(J11)-COLUMN($D$11)+1)) | K11: =IF(MONTH($BC$2)<>MONTH($BC$2-(WEEKDAY($BC$2,1)-($AX$6-1))-IF((WEEKDAY($BC$2,1)-($AX$6-1))<=0,7,0)+(ROW(K11)-ROW($D$11))*7+(COLUMN(K11)-COLUMN($D$11)+1)),"",$BC$2-(WEEKDAY($BC$2,1)-($AX$6-1))-IF((WEEKDAY($BC$2,1)-($AX$6-1))<=0,7,0)+(ROW(K11)-ROW($D$11))*7+(COLUMN(K11)-COLUMN($D$11)+1)) | L11: =IFERROR(IF(MONTH($BC$2)<>MONTH($BC$2-(WEEKDAY($BC$2,1)-($AX$6-1))-IF((WEEKDAY($BC$2,1)-($AX$6-1))<=0,7,0)+(ROW(L11)-ROW($D$11))*7+(COLUMN(L11)-COLUMN($D$11)+1)),"",$BC$2-(WEEKDAY($BC$2,1)-($AX$6-1))-IF((WEEKDAY($BC$2,1)-($AX$6-1))<=0,7,0)+(ROW(L11)-ROW($D$11))*7+(COLUMN(L11)-COLUMN($D$11)+1)),"") | M11: =IFERROR(IF(MONTH($BC$2)<>MONTH($BC$2-(WEEKDAY($BC$2,1)-($AX$6-1))-IF((WEEKDAY($BC$2,1)-($AX$6-1))<=0,7,0)+(ROW(M11)-ROW($D$11))*7+(COLUMN(M11)-COLUMN($D$11)+1)),"",$BC$2-(WEEKDAY($BC$2,1)-($AX$6-1))-IF((WEEKDAY($BC$2,1)-($AX$6-1))<=0,7,0)+(ROW(M11)-ROW($D$11))*7+(COLUMN(M11)-COLUMN($D$11)+1)),"") | N11: =IFERROR(IF(MONTH($BC$2)<>MONTH($BC$2-(WEEKDAY($BC$2,1)-($AX$6-1))-IF((WEEKDAY($BC$2,1)-($AX$6-1))<=0,7,0)+(ROW(N11)-ROW($D$11))*7+(COLUMN(N11)-COLUMN($D$11)+1)),"",$BC$2-(WEEKDAY($BC$2,1)-($AX$6-1))-IF((WEEKDAY($BC$2,1)-($AX$6-1))<=0,7,0)+(ROW(N11)-ROW($D$11))*7+(COLUMN(N11)-COLUMN($D$11)+1)),"") | O11: =IFERROR(IF(MONTH($BC$2)<>MONTH($BC$2-(WEEKDAY($BC$2,1)-($AX$6-1))-IF((WEEKDAY($BC$2,1)-($AX$6-1))<=0,7,0)+(ROW(O11)-ROW($D$11))*7+(COLUMN(O11)-COLUMN($D$11)+1)),"",$BC$2-(WEEKDAY($BC$2,1)-($AX$6-1))-IF((WEEKDAY($BC$2,1)-($AX$6-1))<=0,7,0)+(ROW(O11)-ROW($D$11))*7+(COLUMN(O11)-COLUMN($D$11)+1)),"") | P11: =IFERROR(IF(MONTH($BC$2)<>MONTH($BC$2-(WEEKDAY($BC$2,1)-($AX$6-1))-IF((WEEKDAY($BC$2,1)-($AX$6-1))<=0,7,0)+(ROW(P11)-ROW($D$11))*7+(COLUMN(P11)-COLUMN($D$11)+1)),"",$BC$2-(WEEKDAY($BC$2,1)-($AX$6-1))-IF((WEEKDAY($BC$2,1)-($AX$6-1))<=0,7,0)+(ROW(P11)-ROW($D$11))*7+(COLUMN(P11)-COLUMN($D$11)+1)),"") | Q11: =IF(MONTH($BC$2)<>MONTH($BC$2-(WEEKDAY($BC$2,1)-($AX$6-1))-IF((WEEKDAY($BC$2,1)-($AX$6-1))<=0,7,0)+(ROW(Q11)-ROW($D$11))*7+(COLUMN(Q11)-COLUMN($D$11)+1)),"",$BC$2-(WEEKDAY($BC$2,1)-($AX$6-1))-IF((WEEKDAY($BC$2,1)-($AX$6-1))<=0,7,0)+(ROW(Q11)-ROW($D$11))*7+(COLUMN(Q11)-COLUMN($D$11)+1)) | R11: =IF(MONTH($BC$2)<>MONTH($BC$2-(WEEKDAY($BC$2,1)-($AX$6-1))-IF((WEEKDAY($BC$2,1)-($AX$6-1))<=0,7,0)+(ROW(R11)-ROW($D$11))*7+(COLUMN(R11)-COLUMN($D$11)+1)),"",$BC$2-(WEEKDAY($BC$2,1)-($AX$6-1))-IF((WEEKDAY($BC$2,1)-($AX$6-1))<=0,7,0)+(ROW(R11)-ROW($D$11))*7+(COLUMN(R11)-COLUMN($D$11)+1)) | S11: =IFERROR(IF(MONTH($BC$2)<>MONTH($BC$2-(WEEKDAY($BC$2,1)-($AX$6-1))-IF((WEEKDAY($BC$2,1)-($AX$6-1))<=0,7,0)+(ROW(S11)-ROW($D$11))*7+(COLUMN(S11)-COLUMN($D$11)+1)),"",$BC$2-(WEEKDAY($BC$2,1)-($AX$6-1))-IF((WEEKDAY($BC$2,1)-($AX$6-1))<=0,7,0)+(ROW(S11)-ROW($D$11))*7+(COLUMN(S11)-COLUMN($D$11)+1)),"") | T11: =IFERROR(IF(MONTH($BC$2)<>MONTH($BC$2-(WEEKDAY($BC$2,1)-($AX$6-1))-IF((WEEKDAY($BC$2,1)-($AX$6-1))<=0,7,0)+(ROW(T11)-ROW($D$11))*7+(COLUMN(T11)-COLUMN($D$11)+1)),"",$BC$2-(WEEKDAY($BC$2,1)-($AX$6-1))-IF((WEEKDAY($BC$2,1)-($AX$6-1))<=0,7,0)+(ROW(T11)-ROW($D$11))*7+(COLUMN(T11)-COLUMN($D$11)+1)),"") | U11: =IFERROR(IF(MONTH($BC$2)<>MONTH($BC$2-(WEEKDAY($BC$2,1)-($AX$6-1))-IF((WEEKDAY($BC$2,1)-($AX$6-1))<=0,7,0)+(ROW(U11)-ROW($D$11))*7+(COLUMN(U11)-COLUMN($D$11)+1)),"",$BC$2-(WEEKDAY($BC$2,1)-($AX$6-1))-IF((WEEKDAY($BC$2,1)-($AX$6-1))<=0,7,0)+(ROW(U11)-ROW($D$11))*7+(COLUMN(U11)-COLUMN($D$11)+1)),"") | V11: =IFERROR(IF(MONTH($BC$2)<>MONTH($BC$2-(WEEKDAY($BC$2,1)-($AX$6-1))-IF((WEEKDAY($BC$2,1)-($AX$6-1))<=0,7,0)+(ROW(V11)-ROW($D$11))*7+(COLUMN(V11)-COLUMN($D$11)+1)),"",$BC$2-(WEEKDAY($BC$2,1)-($AX$6-1))-IF((WEEKDAY($BC$2,1)-($AX$6-1))<=0,7,0)+(ROW(V11)-ROW($D$11))*7+(COLUMN(V11)-COLUMN($D$11)+1)),"") | W11: =IFERROR(IF(MONTH($BC$2)<>MONTH($BC$2-(WEEKDAY($BC$2,1)-($AX$6-1))-IF((WEEKDAY($BC$2,1)-($AX$6-1))<=0,7,0)+(ROW(W11)-ROW($D$11))*7+(COLUMN(W11)-COLUMN($D$11)+1)),"",$BC$2-(WEEKDAY($BC$2,1)-($AX$6-1))-IF((WEEKDAY($BC$2,1)-($AX$6-1))<=0,7,0)+(ROW(W11)-ROW($D$11))*7+(COLUMN(W11)-COLUMN($D$11)+1)),"") | X11: =IF(MONTH($BC$2)<>MONTH($BC$2-(WEEKDAY($BC$2,1)-($AX$6-1))-IF((WEEKDAY($BC$2,1)-($AX$6-1))<=0,7,0)+(ROW(X11)-ROW($D$11))*7+(COLUMN(X11)-COLUMN($D$11)+1)),"",$BC$2-(WEEKDAY($BC$2,1)-($AX$6-1))-IF((WEEKDAY($BC$2,1)-($AX$6-1))<=0,7,0)+(ROW(X11)-ROW($D$11))*7+(COLUMN(X11)-COLUMN($D$11)+1)) | Y11: =IF(MONTH($BC$2)<>MONTH($BC$2-(WEEKDAY($BC$2,1)-($AX$6-1))-IF((WEEKDAY($BC$2,1)-($AX$6-1))<=0,7,0)+(ROW(Y11)-ROW($D$11))*7+(COLUMN(Y11)-COLUMN($D$11)+1)),"",$BC$2-(WEEKDAY($BC$2,1)-($AX$6-1))-IF((WEEKDAY($BC$2,1)-($AX$6-1))<=0,7,0)+(ROW(Y11)-ROW($D$11))*7+(COLUMN(Y11)-COLUMN($D$11)+1)) | Z11: =IFERROR(IF(MONTH($BC$2)<>MONTH($BC$2-(WEEKDAY($BC$2,1)-($AX$6-1))-IF((WEEKDAY($BC$2,1)-($AX$6-1))<=0,7,0)+(ROW(Z11)-ROW($D$11))*7+(COLUMN(Z11)-COLUMN($D$11)+1)),"",$BC$2-(WEEKDAY($BC$2,1)-($AX$6-1))-IF((WEEKDAY($BC$2,1)-($AX$6-1))<=0,7,0)+(ROW(Z11)-ROW($D$11))*7+(COLUMN(Z11)-COLUMN($D$11)+1)),"") | AA11: =IFERROR(IF(MONTH($BC$2)<>MONTH($BC$2-(WEEKDAY($BC$2,1)-($AX$6-1))-IF((WEEKDAY($BC$2,1)-($AX$6-1))<=0,7,0)+(ROW(AA11)-ROW($D$11))*7+(COLUMN(AA11)-COLUMN($D$11)+1)),"",$BC$2-(WEEKDAY($BC$2,1)-($AX$6-1))-IF((WEEKDAY($BC$2,1)-($AX$6-1))<=0,7,0)+(ROW(AA11)-ROW($D$11))*7+(COLUMN(AA11)-COLUMN($D$11)+1)),"") | AB11: =IFERROR(IF(MONTH($BC$2)<>MONTH($BC$2-(WEEKDAY($BC$2,1)-($AX$6-1))-IF((WEEKDAY($BC$2,1)-($AX$6-1))<=0,7,0)+(ROW(AB11)-ROW($D$11))*7+(COLUMN(AB11)-COLUMN($D$11)+1)),"",$BC$2-(WEEKDAY($BC$2,1)-($AX$6-1))-IF((WEEKDAY($BC$2,1)-($AX$6-1))<=0,7,0)+(ROW(AB11)-ROW($D$11))*7+(COLUMN(AB11)-COLUMN($D$11)+1)),"") | AC11: =IFERROR(IF(MONTH($BC$2)<>MONTH($BC$2-(WEEKDAY($BC$2,1)-($AX$6-1))-IF((WEEKDAY($BC$2,1)-($AX$6-1))<=0,7,0)+(ROW(AC11)-ROW($D$11))*7+(COLUMN(AC11)-COLUMN($D$11)+1)),"",$BC$2-(WEEKDAY($BC$2,1)-($AX$6-1))-IF((WEEKDAY($BC$2,1)-($AX$6-1))<=0,7,0)+(ROW(AC11)-ROW($D$11))*7+(COLUMN(AC11)-COLUMN($D$11)+1)),"") | AD11: =IFERROR(IF(MONTH($BC$2)<>MONTH($BC$2-(WEEKDAY($BC$2,1)-($AX$6-1))-IF((WEEKDAY($BC$2,1)-($AX$6-1))<=0,7,0)+(ROW(AD11)-ROW($D$11))*7+(COLUMN(AD11)-COLUMN($D$11)+1)),"",$BC$2-(WEEKDAY($BC$2,1)-($AX$6-1))-IF((WEEKDAY($BC$2,1)-($AX$6-1))<=0,7,0)+(ROW(AD11)-ROW($D$11))*7+(COLUMN(AD11)-COLUMN($D$11)+1)),"") | AE11: =IF(MONTH($BC$2)<>MONTH($BC$2-(WEEKDAY($BC$2,1)-($AX$6-1))-IF((WEEKDAY($BC$2,1)-($AX$6-1))<=0,7,0)+(ROW(AE11)-ROW($D$11))*7+(COLUMN(AE11)-COLUMN($D$11)+1)),"",$BC$2-(WEEKDAY($BC$2,1)-($AX$6-1))-IF((WEEKDAY($BC$2,1)-($AX$6-1))<=0,7,0)+(ROW(AE11)-ROW($D$11))*7+(COLUMN(AE11)-COLUMN($D$11)+1)) | AF11: =IF(MONTH($BC$2)<>MONTH($BC$2-(WEEKDAY($BC$2,1)-($AX$6-1))-IF((WEEKDAY($BC$2,1)-($AX$6-1))<=0,7,0)+(ROW(AF11)-ROW($D$11))*7+(COLUMN(AF11)-COLUMN($D$11)+1)),"",$BC$2-(WEEKDAY($BC$2,1)-($AX$6-1))-IF((WEEKDAY($BC$2,1)-($AX$6-1))<=0,7,0)+(ROW(AF11)-ROW($D$11))*7+(COLUMN(AF11)-COLUMN($D$11)+1)) | AG11: =IFERROR(IF(MONTH($BC$2)<>MONTH($BC$2-(WEEKDAY($BC$2,1)-($AX$6-1))-IF((WEEKDAY($BC$2,1)-($AX$6-1))<=0,7,0)+(ROW(AG11)-ROW($D$11))*7+(COLUMN(AG11)-COLUMN($D$11)+1)),"",$BC$2-(WEEKDAY($BC$2,1)-($AX$6-1))-IF((WEEKDAY($BC$2,1)-($AX$6-1))<=0,7,0)+(ROW(AG11)-ROW($D$11))*7+(COLUMN(AG11)-COLUMN($D$11)+1)),"") | AH11: =IFERROR(IF(MONTH($BC$2)<>MONTH($BC$2-(WEEKDAY($BC$2,1)-($AX$6-1))-IF((WEEKDAY($BC$2,1)-($AX$6-1))<=0,7,0)+(ROW(AH11)-ROW($D$11))*7+(COLUMN(AH11)-COLUMN($D$11)+1)),"",$BC$2-(WEEKDAY($BC$2,1)-($AX$6-1))-IF((WEEKDAY($BC$2,1)-($AX$6-1))<=0,7,0)+(ROW(AH11)-ROW($D$11))*7+(COLUMN(AH11)-COLUMN($D$11)+1)),"") | AI11: =IFERROR(IF(MONTH($BC$2)<>MONTH($BC$2-(WEEKDAY($BC$2,1)-($AX$6-1))-IF((WEEKDAY($BC$2,1)-($AX$6-1))<=0,7,0)+(ROW(AI11)-ROW($D$11))*7+(COLUMN(AI11)-COLUMN($D$11)+1)),"",$BC$2-(WEEKDAY($BC$2,1)-($AX$6-1))-IF((WEEKDAY($BC$2,1)-($AX$6-1))<=0,7,0)+(ROW(AI11)-ROW($D$11))*7+(COLUMN(AI11)-COLUMN($D$11)+1)),"") | AJ11: =IFERROR(IF(MONTH($BC$2)<>MONTH($BC$2-(WEEKDAY($BC$2,1)-($AX$6-1))-IF((WEEKDAY($BC$2,1)-($AX$6-1))<=0,7,0)+(ROW(AJ11)-ROW($D$11))*7+(COLUMN(AJ11)-COLUMN($D$11)+1)),"",$BC$2-(WEEKDAY($BC$2,1)-($AX$6-1))-IF((WEEKDAY($BC$2,1)-($AX$6-1))<=0,7,0)+(ROW(AJ11)-ROW($D$11))*7+(COLUMN(AJ11)-COLUMN($D$11)+1)),"") | AK11: =IFERROR(IF(MONTH($BC$2)<>MONTH($BC$2-(WEEKDAY($BC$2,1)-($AX$6-1))-IF((WEEKDAY($BC$2,1)-($AX$6-1))<=0,7,0)+(ROW(AK11)-ROW($D$11))*7+(COLUMN(AK11)-COLUMN($D$11)+1)),"",$BC$2-(WEEKDAY($BC$2,1)-($AX$6-1))-IF((WEEKDAY($BC$2,1)-($AX$6-1))<=0,7,0)+(ROW(AK11)-ROW($D$11))*7+(COLUMN(AK11)-COLUMN($D$11)+1)),"") | AL11: =IF(MONTH($BC$2)<>MONTH($BC$2-(WEEKDAY($BC$2,1)-($AX$6-1))-IF((WEEKDAY($BC$2,1)-($AX$6-1))<=0,7,0)+(ROW(AL11)-ROW($D$11))*7+(COLUMN(AL11)-COLUMN($D$11)+1)),"",$BC$2-(WEEKDAY($BC$2,1)-($AX$6-1))-IF((WEEKDAY($BC$2,1)-($AX$6-1))<=0,7,0)+(ROW(AL11)-ROW($D$11))*7+(COLUMN(AL11)-COLUMN($D$11)+1)) | AM11: =IF(MONTH($BC$2)<>MONTH($BC$2-(WEEKDAY($BC$2,1)-($AX$6-1))-IF((WEEKDAY($BC$2,1)-($AX$6-1))<=0,7,0)+(ROW(AM11)-ROW($D$11))*7+(COLUMN(AM11)-COLUMN($D$11)+1)),"",$BC$2-(WEEKDAY($BC$2,1)-($AX$6-1))-IF((WEEKDAY($BC$2,1)-($AX$6-1))<=0,7,0)+(ROW(AM11)-ROW($D$11))*7+(COLUMN(AM11)-COLUMN($D$11)+1)) | AN11: =IFERROR(IF(MONTH($BC$2)<>MONTH($BC$2-(WEEKDAY($BC$2,1)-($AX$6-1))-IF((WEEKDAY($BC$2,1)-($AX$6-1))<=0,7,0)+(ROW(AN11)-ROW($D$11))*7+(COLUMN(AN11)-COLUMN($D$11)+1)),"",$BC$2-(WEEKDAY($BC$2,1)-($AX$6-1))-IF((WEEKDAY($BC$2,1)-($AX$6-1))<=0,7,0)+(ROW(AN11)-ROW($D$11))*7+(COLUMN(AN11)-COLUMN($D$11)+1)),"") | BD11: TRANSFERRED OUT | BE11: 3 | BG11: =COUNTIF($BD$13:$BD$52,"3") | BH11: =COUNTIF($BD$54:$BD$93,"3")
D12: S | E12: M | F12: T | G12: W | H12: TH | I12: F | J12: SAT | K12: S | L12: M | M12: T | N12: W | O12: TH | P12: F | Q12: SAT | R12: S | S12: M | T12: T | U12: W | V12: TH | W12: F | X12: SAT | Y12: S | Z12: M | AA12: T | AB12: W | AC12: TH | AD12: F | AE12: SAT | AF12: S | AG12: M | AH12: T | AI12: W | AJ12: TH | AK12: F | AL12: SAT | AM12: S | AN12: M | AO12: ABSENT | AP12: TARDY | BA12: HOLIDAYS | BD12: TRANSFERRED IN | BE12: 4 | BG12: =COUNTIF($BD$13:$BD$52,"4") | BH12: =COUNTIF($BD$54:$BD$93,"4")
A13: =IF(B13="","",1) | B13: =IF(Names!B5="","",Names!B5) | AO13: =AO135 | AP13: =IF(B13="","",AO227) | AW13: =IF(AQ13="","",VLOOKUP(AQ13,$BD$9:$BE$12,2,0)) | AX13: JANUARY | AY13: 1 | AZ13: =$AY$3+1 | BA13: =IF(BB13=$AG$6,BC13,0) | BB13: =Holidays!B6 | BC13: =Holidays!C6 | BD13: =IF(B13="","",AW13) | BE13: 1. CODES FOR CHECKING ATTENDANCE
A14: =IF(B14="","",A13+1) | B14: =IF(Names!B6="","",Names!B6) | AO14: =AO136 | AP14: =IF(B14="","",AO228) | AW14: =IF(AQ14="","",VLOOKUP(AQ14,$BD$9:$BE$12,2,0)) | AX14: FEBRUARY | AY14: 2 | AZ14: =$AY$3+1 | BA14: =IF(BB14=$AG$6,BC14,0) | BB14: =Holidays!B7 | BC14: =Holidays!C7 | BD14: =IF(B14="","",AW14) | BE14: (blank) - Present; (x)- Absent; Tardy (T)
A15: =IF(B15="","",A14+1) | B15: =IF(Names!B7="","",Names!B7) | AO15: =AO137 | AP15: =IF(B15="","",AO229) | AW15: =IF(AQ15="","",VLOOKUP(AQ15,$BD$9:$BE$12,2,0)) | AX15: MARCH | AY15: 3 | AZ15: =$AY$3+1 | BA15: =IF(BB15=$AG$6,BC15,0) | BB15: =Holidays!B8 | BC15: =Holidays!C8 | BD15: =IF(B15="","",AW15)
A16: =IF(B16="","",A15+1) | B16: =IF(Names!B8="","",Names!B8) | AO16: =AO138 | AP16: =IF(B16="","",AO230) | AW16: =IF(AQ16="","",VLOOKUP(AQ16,$BD$9:$BE$12,2,0)) | AX16: APRIL | AY16: 4 | AZ16: =$AY$3+1 | BA16: =IF(BB16=$AG$6,BC16,0) | BB16: =Holidays!B9 | BC16: =Holidays!C9 | BD16: =IF(B16="","",AW16) | BE16: 2. REASONS/CAUSES FOR DROPPING OUT
A17: =IF(B17="","",A16+1) | B17: =IF(Names!B9="","",Names!B9) | AO17: =AO139 | AP17: =IF(B17="","",AO231) | AW17: =IF(AQ17="","",VLOOKUP(AQ17,$BD$9:$BE$12,2,0)) | AX17: MAY | AY17: 5 | AZ17: =$AY$3+1 | BA17: =IF(BB17=$AG$6,BC17,0) | BB17: =Holidays!B10 | BC17: =Holidays!C10 | BD17: =IF(B17="","",AW17) | BE17: a. Domestic-Related Factors | BG17: a.1. Had to take care of siblings
A18: =IF(B18="","",A17+1) | B18: =IF(Names!B10="","",Names!B10) | AO18: =AO140 | AP18: =IF(B18="","",AO232) | AW18: =IF(AQ18="","",VLOOKUP(AQ18,$BD$9:$BE$12,2,0)) | AX18: JUNE | AY18: 6 | AZ18: =$AY$3 | BA18: =IF(BB18=$AG$6,BC18,0) | BB18: =Holidays!B11 | BC18: =Holidays!C11 | BD18: =IF(B18="","",AW18) | BG18: a.2. Early marriage/pregnancy
A19: =IF(B19="","",A18+1) | B19: =IF(Names!B11="","",Names!B11) | AO19: =AO141 | AP19: =IF(B19="","",AO233) | AW19: =IF(AQ19="","",VLOOKUP(AQ19,$BD$9:$BE$12,2,0)) | AX19: JULY | AY19: 7 | AZ19: =$AY$3 | BA19: =IF(BB19=$AG$6,BC19,0) | BB19: =Holidays!B12 | BC19: =Holidays!C12 | BD19: =IF(B19="","",AW19) | BG19: a.3. Parents' attitude toward schooling
A20: =IF(B20="","",A19+1) | B20: =IF(Names!B12="","",Names!B12) | AO20: =AO142 | AP20: =IF(B20="","",AO234) | AW20: =IF(AQ20="","",VLOOKUP(AQ20,$BD$9:$BE$12,2,0)) | AX20: AUGUST | AY20: 8 | AZ20: =$AY$3 | BA20: =IF(BB20=$AG$6,BC20,0) | BB20: =Holidays!B13 | BC20: =Holidays!C13 | BD20: =IF(B20="","",AW20) | BG20: a.4. Family problems
A21: =IF(B21="","",A20+1) | B21: =IF(Names!B13="","",Names!B13) | AO21: =AO143 | AP21: =IF(B21="","",AO235) | AW21: =IF(AQ21="","",VLOOKUP(AQ21,$BD$9:$BE$12,2,0)) | AX21: SEPTEMBER | AY21: 9 | AZ21: =$AY$3 | BA21: =IF(BB21=$AG$6,BC21,0) | BB21: =Holidays!B14 | BC21: =Holidays!C14 | BD21: =IF(B21="","",AW21) | BE21: b. Individual-Related Factors | BG21: b.1. Illness
A22: =IF(B22="","",A21+1) | B22: =IF(Names!B14="","",Names!B14) | AO22: =AO144 | AP22: =IF(B22="","",AO236) | AW22: =IF(AQ22="","",VLOOKUP(AQ22,$BD$9:$BE$12,2,0)) | AX22: OCTOBER | AY22: 10 | AZ22: =$AY$3 | BA22: =IF(BB22=$AG$6,BC22,0) | BB22: =Holidays!B15 | BC22: =Holidays!C15 | BD22: =IF(B22="","",AW22) | BG22: b.2. Overage
A23: =IF(B23="","",A22+1) | B23: =IF(Names!B15="","",Names!B15) | AO23: =AO145 | AP23: =IF(B23="","",AO237) | AW23: =IF(AQ23="","",VLOOKUP(AQ23,$BD$9:$BE$12,2,0)) | AX23: NOVEMBER | AY23: 11 | AZ23: =$AY$3 | BA23: =IF(BB23=$AG$6,BC23,0) | BB23: =Holidays!B16 | BC23: =Holidays!C16 | BD23: =IF(B23="","",AW23) | BG23: b.3. Death
A24: =IF(B24="","",A23+1) | B24: =IF(Names!B16="","",Names!B16) | AO24: =AO146 | AP24: =IF(B24="","",AO238) | AW24: =IF(AQ24="","",VLOOKUP(AQ24,$BD$9:$BE$12,2,0)) | AX24: DECEMBER | AY24: 12 | AZ24: =$AY$3 | BA24: =IF(BB24=$AG$6,BC24,0) | BB24: =Holidays!B17 | BC24: =Holidays!C17 | BD24: =IF(B24="","",AW24) | BG24: b.4. Drug Abuse
A25: =IF(B25="","",A24+1) | B25: =IF(Names!B17="","",Names!B17) | AO25: =AO147 | AP25: =IF(B25="","",AO239) | AW25: =IF(AQ25="","",VLOOKUP(AQ25,$BD$9:$BE$12,2,0)) | AY25: 13 | BA25: =IF(BB25=$AG$6,BC25,0) | BB25: =Holidays!B18 | BC25: =Holidays!C18 | BD25: =IF(B25="","",AW25) | BG25: b.5. Poor academic performance
A26: =IF(B26="","",A25+1) | B26: =IF(Names!B18="","",Names!B18) | AO26: =AO148 | AP26: =IF(B26="","",AO240) | AW26: =IF(AQ26="","",VLOOKUP(AQ26,$BD$9:$BE$12,2,0)) | BA26: =IF(BB26=$AG$6,BC26,0) | BB26: =Holidays!B19 | BC26: =Holidays!C19 | BD26: =IF(B26="","",AW26) | BG26: b.6. Lack of interest/Distractions
A27: =IF(B27="","",A26+1) | B27: =IF(Names!B19="","",Names!B19) | AO27: =AO149 | AP27: =IF(B27="","",AO241) | AW27: =IF(AQ27="","",VLOOKUP(AQ27,$BD$9:$BE$12,2,0)) | BA27: =IF(BB27=$AG$6,BC27,0) | BB27: =Holidays!B20 | BC27: =Holidays!C20 | BD27: =IF(B27="","",AW27) | BG27: b.7. Hunger/Malnutrition
A28: =IF(B28="","",A27+1) | B28: =IF(Names!B20="","",Names!B20) | AO28: =AO150 | AP28: =IF(B28="","",AO242) | AW28: =IF(AQ28="","",VLOOKUP(AQ28,$BD$9:$BE$12,2,0)) | BA28: =IF(BB28=$AG$6,BC28,0) | BB28: =Holidays!B21 | BC28: =Holidays!C21 | BD28: =IF(B28="","",AW28) | BE28: c. School-Related Factors | BG28: c.1. Teacher Factor
A29: =IF(B29="","",A28+1) | B29: =IF(Names!B21="","",Names!B21) | AO29: =AO151 | AP29: =IF(B29="","",AO243) | AW29: =IF(AQ29="","",VLOOKUP(AQ29,$BD$9:$BE$12,2,0)) | BA29: =IF(BB29=$AG$6,BC29,0) | BB29: =Holidays!B22 | BC29: =Holidays!C22 | BD29: =IF(B29="","",AW29) | BG29: c.2. Physical condition of classroom
A30: =IF(B30="","",A29+1) | B30: =IF(Names!B22="","",Names!B22) | AO30: =AO152 | AP30: =IF(B30="","",AO244) | AW30: =IF(AQ30="","",VLOOKUP(AQ30,$BD$9:$BE$12,2,0)) | BA30: =IF(BB30=$AG$6,BC30,0) | BB30: =Holidays!B23 | BC30: =Holidays!C23 | BD30: =IF(B30="","",AW30) | BG30: c.3. Peer influence
A31: =IF(B31="","",A30+1) | B31: =IF(Names!B23="","",Names!B23) | AO31: =AO153 | AP31: =IF(B31="","",AO245) | AW31: =IF(AQ31="","",VLOOKUP(AQ31,$BD$9:$BE$12,2,0)) | BA31: =IF(BB31=$AG$6,BC31,0) | BB31: =Holidays!B24 | BC31: =Holidays!C24 | BD31: =IF(B31="","",AW31) | BE31: d. Geographic/Environmental | BG31: d.1. Distance between home and school
A32: =IF(B32="","",A31+1) | B32: =IF(Names!B24="","",Names!B24) | AO32: =AO154 | AP32: =IF(B32="","",AO246) | AW32: =IF(AQ32="","",VLOOKUP(AQ32,$BD$9:$BE$12,2,0)) | BA32: =IF(BB32=$AG$6,BC32,0) | BB32: =Holidays!B25 | BC32: =Holidays!C25 | BD32: =IF(B32="","",AW32) | BG32: d.2. Armed conflict (incl. Tribal wars & clanfeuds)
A33: =IF(B33="","",A32+1) | B33: =IF(Names!B25="","",Names!B25) | AO33: =AO155 | AP33: =IF(B33="","",AO247) | AW33: =IF(AQ33="","",VLOOKUP(AQ33,$BD$9:$BE$12,2,0)) | BA33: =IF(BB33=$AG$6,BC33,0) | BB33: =Holidays!B26 | BC33: =Holidays!C26 | BD33: =IF(B33="","",AW33) | BG33: d.3. Calamities/Disasters
A34: =IF(B34="","",A33+1) | B34: =IF(Names!B26="","",Names!B26) | AO34: =AO156 | AP34: =IF(B34="","",AO248) | AW34: =IF(AQ34="","",VLOOKUP(AQ34,$BD$9:$BE$12,2,0)) | BA34: =IF(BB34=$AG$6,BC34,0) | BB34: =Holidays!B27 | BC34: =Holidays!C27 | BD34: =IF(B34="","",AW34) | BE34: e. Financial-Related | BG34: e.1. Child labor, work
A35: =IF(B35="","",A34+1) | B35: =IF(Names!B27="","",Names!B27) | AO35: =AO157 | AP35: =IF(B35="","",AO249) | AW35: =IF(AQ35="","",VLOOKUP(AQ35,$BD$9:$BE$12,2,0)) | BA35: =IF(BB35=$AG$6,BC35,0) | BB35: =Holidays!B28 | BC35: =Holidays!C28 | BD35: =IF(B35="","",AW35) | BE35: f. Others (Specify) | BG35: =CONCATENATE("f."," ",BG36)
A36: =IF(B36="","",A35+1) | B36: =IF(Names!B28="","",Names!B28) | AO36: =AO158 | AP36: =IF(B36="","",AO250) | AW36: =IF(AQ36="","",VLOOKUP(AQ36,$BD$9:$BE$12,2,0)) | BA36: =IF(BB36=$AG$6,BC36,0) | BB36: =Holidays!B29 | BC36: =Holidays!C29 | BD36: =IF(B36="","",AW36)
A37: =IF(B37="","",A36+1) | B37: =IF(Names!B29="","",Names!B29) | AO37: =AO159 | AP37: =IF(B37="","",AO251) | AW37: =IF(AQ37="","",VLOOKUP(AQ37,$BD$9:$BE$12,2,0)) | BA37: =IF(BB37=$AG$6,BC37,0) | BB37: =Holidays!B30 | BC37: =Holidays!C30 | BD37: =IF(B37="","",AW37)
A38: =IF(B38="","",A37+1) | B38: =IF(Names!B30="","",Names!B30) | AO38: =AO160 | AP38: =IF(B38="","",AO252) | AW38: =IF(AQ38="","",VLOOKUP(AQ38,$BD$9:$BE$12,2,0)) | BA38: =IF(BB38=$AG$6,BC38,0) | BB38: =Holidays!B31 | BC38: =Holidays!C31 | BD38: =IF(B38="","",AW38)
A39: =IF(B39="","",A38+1) | B39: =IF(Names!B31="","",Names!B31) | AO39: =AO161 | AP39: =IF(B39="","",AO253) | AW39: =IF(AQ39="","",VLOOKUP(AQ39,$BD$9:$BE$12,2,0)) | BA39: =IF(BB39=$AG$6,BC39,0) | BB39: =Holidays!B32 | BC39: =Holidays!C32 | BD39: =IF(B39="","",AW39)
A40: =IF(B40="","",A39+1) | B40: =IF(Names!B32="","",Names!B32) | AO40: =AO162 | AP40: =IF(B40="","",AO254) | AW40: =IF(AQ40="","",VLOOKUP(AQ40,$BD$9:$BE$12,2,0)) | BA40: =IF(BB40=$AG$6,BC40,0) | BB40: =Holidays!B33 | BC40: =Holidays!C33 | BD40: =IF(B40="","",AW40)
A41: =IF(B41="","",A40+1) | B41: =IF(Names!B33="","",Names!B33) | AO41: =AO163 | AP41: =IF(B41="","",AO255) | AW41: =IF(AQ41="","",VLOOKUP(AQ41,$BD$9:$BE$12,2,0)) | BA41: =IF(BB41=$AG$6,BC41,0) | BB41: =Holidays!B34 | BC41: =Holidays!C34 | BD41: =IF(B41="","",AW41)
A42: =IF(B42="","",A41+1) | B42: =IF(Names!B34="","",Names!B34) | AO42: =AO164 | AP42: =IF(B42="","",AO256) | AW42: =IF(AQ42="","",VLOOKUP(AQ42,$BD$9:$BE$12,2,0)) | BA42: =IF(BB42=$AG$6,BC42,0) | BB42: =Holidays!B35 | BC42: =Holidays!C35 | BD42: =IF(B42="","",AW42)
A43: =IF(B43="","",A42+1) | B43: =IF(Names!B35="","",Names!B35) | AO43: =AO165 | AP43: =IF(B43="","",AO257) | AW43: =IF(AQ43="","",VLOOKUP(AQ43,$BD$9:$BE$12,2,0)) | BA43: =IF(BB43=$AG$6,BC43,0) | BB43: =Holidays!B36 | BC43: =Holidays!C36 | BD43: =IF(B43="","",AW43)
A44: =IF(B44="","",A43+1) | B44: =IF(Names!B36="","",Names!B36) | AO44: =AO166 | AP44: =IF(B44="","",AO258) | AW44: =IF(AQ44="","",VLOOKUP(AQ44,$BD$9:$BE$12,2,0)) | BA44: =IF(BB44=$AG$6,BC44,0) | BB44: =Holidays!B37 | BC44: =Holidays!C37 | BD44: =IF(B44="","",AW44)
...

Sheet SF2 (AUG)
A2: School Form 2 (SF2) Daily Attendance Report of Learners | AX2: MONTH | AY2: =IF(AG6="","",VLOOKUP(AG6,AX13:AY25,2,0)) | AZ2: YEAR | BA2: =VLOOKUP(AY2,AY13:AZ24,2,0) | BB2: DATE | BC2: =DATE(BA2,AY2,1)
A3: (This replaces Form 1, Form 2 & STS Form 4 - Absenteeism and Dropout Profile) | AX3: YEAR | AY3: =CONCATENATE(AX8,AY8,AZ8,BA8)
B6: School ID | C6: =IF(Names!Q4="","",Names!Q4) | J6: School Year | N6: =IF(Names!Q5="","",Names!Q5) | V6: Report for the Month of | AG6: AUGUST | AX6: 1 | BC6: =MONTH(BC2)
B8: Name of School | C8: =IF(Names!Q8="","",UPPER(Names!Q8)) | AA8: Grade Level | AG8: =IF(Names!Q6="","",Names!Q6) | AI8: Section | AO8: =IF(Names!Q7="","",UPPER(Names!Q7)) | AX8: =MID($N$6,1,1) | AY8: =MID($N$6,2,1) | AZ8: =MID($N$6,3,1) | BA8: =MID($N$6,4,1) | BG8: MALE | BH8: FEMALE
BE9: 1
A10: LEARNER'S NAME (Last Name, First Name, Middle Name) | D10: (1st row for date) | AO10: Total for the Month | AQ10: REMARKS (If DROPPED OUT, state reason, please refer to legend number 2. If TRANSFERRED IN/OUT, write the name of School.) | BD10: DROPPED OUT | BE10: 2 | BG10: =COUNTIF($BD$13:$BD$52,"2") | BH10: =COUNTIF($BD$54:$BD$93,"2")
