Workbook
Name PERFORMANCETASKS: 'INPUT DATA'!#REF!
Name PT: 'INPUT DATA'!#REF!
Name QA: 'INPUT DATA'!#REF!
Name QUARTERLYASSESSMENT: 'INPUT DATA'!#REF!
Name SUBJECTS: '[1]INPUT DATA'!$A$1002:$A$1005
Name Transmu_Table: 'INPUT DATA'!#REF!
Name WRITTENWORKS: 'INPUT DATA'!#REF!
Name WW: 'INPUT DATA'!#REF!

Sheet INPUT DATA
A1: Input Data Sheet for SHS E-Class Record
C4: REGION | G4: NCR | L4: DIVISION | O4: CITY DIVISION OF MANILA
B5: SCHOOL NAME | G5: ACLC COMPUTER LEARNING CENTER | T5: SCHOOL ID | X5: 401144 | AD5: SCHOOL YEAR | AG5: 2026-2027
A7: LEARNERS' NAMES | F7: GRADE & SECTION: | K7: ICT11-A | Q7: TEACHER: | S7: MR. FRANK NATHAN FAA | AC7: SUBJECT:
Q8: SEMESTER: | S8: 1ST | AC8: TRACK: | AE8: Core Subject (All Tracks)
A12: MALE
A13: 1 | B13: BARRETO, WARREN B.
A14: 2 | B14: FAA, FRANK NATHAN V.
A15: 3 | B15: MAURERA, RIZALDY JOSE M.
A16: 4 | B16: SABEJON, RAFAEL C.
A17: 5 | B17: SAMSON, NEO ERRMON P.
A18: 6 | B18: SANTOS, JASRAJ D.
A19: 7
A20: 8
A21: 9
A22: 10
A23: 11
A24: 12
A25: 13
A26: 14
A27: 15
A28: 16
A29: 17
A30: 18
... A62: 50
A63: FEMALE
A64: 1 | B64: FERNANDEZ , YHUNICE KATE G.
A65: 2 | B65: NAPIZA, ASHLEY R.
A66: 3 | B66: TOLENTINO, LEAH G.
A67: 4
A68: 5
A69: 6
A70: 7
A71: 8
A72: 9
A73: 10
A74: 11
A75: 12
A76: 13
A77: 14
...

Sheet 1ST
A1: Senior High School Class Record
A3: (Pursuant to Deped Order 8 series of 2015)
C4: REGION | G4: ='INPUT DATA'!G4 | L4: DIVISION | O4: ='INPUT DATA'!O4
B5: SCHOOL NAME | G5: ='INPUT DATA'!G5 | T5: SCHOOL ID | X5: ='INPUT DATA'!$X$5 | AD5: SCHOOL YEAR | AG5: ='INPUT DATA'!AG5
A7: =IF('INPUT DATA'!S8="","",IF('INPUT DATA'!S8="1ST","FIRST QUARTER",IF('INPUT DATA'!S8="2ND","THIRD QUARTER"))) | F7: GRADE & SECTION: | K7: ='INPUT DATA'!K7 | Q7: TEACHER: | S7: ='INPUT DATA'!S7 | AC7: SUBJECT: | AE7: ='INPUT DATA'!AE7
Q8: SEMESTER: | S8: ='INPUT DATA'!S8 | AC8: TRACK: | AE8: ='INPUT DATA'!AE8
A9: LEARNERS' NAMES | F9: =IF('INPUT DATA'!AE8="","",INDEX('Helper(IMPORTANT!)'!$AR$2:$AR$5,MATCH(AE8,'Helper(IMPORTANT!)'!$AQ$2:$AQ$5,0))) | S9: =IF('INPUT DATA'!AE8="","",INDEX('Helper(IMPORTANT!)'!$AS$2:$AS$5,MATCH(AE8,'Helper(IMPORTANT!)'!$AQ$2:$AQ$5,0))) | AF9: =IF('INPUT DATA'!AE8="","",INDEX('Helper(IMPORTANT!)'!$AT$2:$AT$5,MATCH(AE8,'Helper(IMPORTANT!)'!$AQ$2:$AQ$5,0))) | AI9: Initial Grade | AJ9: Quarterly Grade
F10: 1 | G10: 2 | H10: 3 | I10: 4 | J10: 5 | K10: 6 | L10: 7 | M10: 8 | N10: 9 | O10: 10 | P10: Total | Q10: PS | R10: WS | S10: 1 | T10: 2 | U10: 3 | V10: 4 | W10: 5 | X10: 6 | Y10: 7 | Z10: 8 | AA10: 9 | AB10: 10 | AC10: Total | AD10: PS | AE10: WS | AF10: 1 | AG10: PS | AH10: WS
A11: HIGHEST POSSIBLE SCORE | P11: =IF(COUNT($F11:$O11)=0,"",SUM($F11:$O11)) | Q11: 100 | R11: =IF('INPUT DATA'!AE8="","",INDEX('Helper(IMPORTANT!)'!$AU$2:$AU$5,MATCH(AE8,'Helper(IMPORTANT!)'!$AQ$2:$AQ$5,0))) | AC11: =IF(COUNT($S11:$AB11)=0,"",SUM($S11:$AB11)) | AD11: 100 | AE11: =IF('INPUT DATA'!AE8="","",INDEX('Helper(IMPORTANT!)'!$AV$2:$AV$5,MATCH(AE8,'Helper(IMPORTANT!)'!$AQ$2:$AQ$5,0))) | AG11: 100 | AH11: =IF('INPUT DATA'!AE8="","",INDEX('Helper(IMPORTANT!)'!$AW$2:$AW$5,MATCH(AE8,'Helper(IMPORTANT!)'!$AQ$2:$AQ$5,0)))
A12: MALE
A13: 1 | B13: ='INPUT DATA'!B13 | P13: =IF(COUNT($F13:$O13)=0,"",SUM($F13:$O13)) | Q13: =IFERROR(IF(P13="","",ROUND(P13/$P$11*100,2)),"") | R13: =IFERROR(IF(Q13="","",ROUND(Q13*$R$11,2)),"") | AC13: =IF(COUNT($S13:$AB13)=0,"",SUM($S13:$AB13)) | AD13: =IFERROR(IF(AC13="","",ROUND(AC13/$AC$11*100,2)),"") | AE13: =IFERROR(IF(AD13="","",ROUND(AD13*$AE$11,2)),"") | AG13: =IFERROR(IF(AF13="","",ROUND(AF13/$AF$11*100,2)),"") | AH13: =IFERROR(IF(AG13="","",ROUND(AG13*$AH$11,2)),"") | AI13: =IFERROR(R13+AE13+AH13,"") | AJ13: =IFERROR(VLOOKUP(AI13,'Helper(IMPORTANT!)'!$AX$1:$AY$41,2,TRUE),"")
A14: 2 | B14: ='INPUT DATA'!B14 | P14: =IF(COUNT($F14:$O14)=0,"",SUM($F14:$O14)) | Q14: =IFERROR(IF(P14="","",ROUND(P14/$P$11*100,2)),"") | R14: =IFERROR(IF(Q14="","",ROUND(Q14*$R$11,2)),"") | AC14: =IF(COUNT($S14:$AB14)=0,"",SUM($S14:$AB14)) | AD14: =IFERROR(IF(AC14="","",ROUND(AC14/$AC$11*100,2)),"") | AE14: =IFERROR(IF(AD14="","",ROUND(AD14*$AE$11,2)),"") | AG14: =IFERROR(IF(AF14="","",ROUND(AF14/$AF$11*100,2)),"") | AH14: =IFERROR(IF(AG14="","",ROUND(AG14*$AH$11,2)),"") | AI14: =IFERROR(R14+AE14+AH14,"") | AJ14: =IFERROR(VLOOKUP(AI14,'Helper(IMPORTANT!)'!$AX$1:$AY$41,2,TRUE),"")
A15: 3 | B15: ='INPUT DATA'!B15 | P15: =IF(COUNT($F15:$O15)=0,"",SUM($F15:$O15)) | Q15: =IFERROR(IF(P15="","",ROUND(P15/$P$11*100,2)),"") | R15: =IFERROR(IF(Q15="","",ROUND(Q15*$R$11,2)),"") | AC15: =IF(COUNT($S15:$AB15)=0,"",SUM($S15:$AB15)) | AD15: =IFERROR(IF(AC15="","",ROUND(AC15/$AC$11*100,2)),"") | AE15: =IFERROR(IF(AD15="","",ROUND(AD15*$AE$11,2)),"") | AG15: =IFERROR(IF(AF15="","",ROUND(AF15/$AF$11*100,2)),"") | AH15: =IFERROR(IF(AG15="","",ROUND(AG15*$AH$11,2)),"") | AI15: =IFERROR(R15+AE15+AH15,"") | AJ15: =IFERROR(VLOOKUP(AI15,'Helper(IMPORTANT!)'!$AX$1:$AY$41,2,TRUE),"")
A16: 4 | B16: ='INPUT DATA'!B16 | P16: =IF(COUNT($F16:$O16)=0,"",SUM($F16:$O16)) | Q16: =IFERROR(IF(P16="","",ROUND(P16/$P$11*100,2)),"") | R16: =IFERROR(IF(Q16="","",ROUND(Q16*$R$11,2)),"") | AC16: =IF(COUNT($S16:$AB16)=0,"",SUM($S16:$AB16)) | AD16: =IFERROR(IF(AC16="","",ROUND(AC16/$AC$11*100,2)),"") | AE16: =IFERROR(IF(AD16="","",ROUND(AD16*$AE$11,2)),"") | AG16: =IFERROR(IF(AF16="","",ROUND(AF16/$AF$11*100,2)),"") | AH16: =IFERROR(IF(AG16="","",ROUND(AG16*$AH$11,2)),"") | AI16: =IFERROR(R16+AE16+AH16,"") | AJ16: =IFERROR(VLOOKUP(AI16,'Helper(IMPORTANT!)'!$AX$1:$AY$41,2,TRUE),"")
A17: 5 | B17: ='INPUT DATA'!B17 | P17: =IF(COUNT($F17:$O17)=0,"",SUM($F17:$O17)) | Q17: =IFERROR(IF(P17="","",ROUND(P17/$P$11*100,2)),"") | R17: =IFERROR(IF(Q17="","",ROUND(Q17*$R$11,2)),"") | AC17: =IF(COUNT($S17:$AB17)=0,"",SUM($S17:$AB17)) | AD17: =IFERROR(IF(AC17="","",ROUND(AC17/$AC$11*100,2)),"") | AE17: =IFERROR(IF(AD17="","",ROUND(AD17*$AE$11,2)),"") | AG17: =IFERROR(IF(AF17="","",ROUND(AF17/$AF$11*100,2)),"") | AH17: =IFERROR(IF(AG17="","",ROUND(AG17*$AH$11,2)),"") | AI17: =IFERROR(R17+AE17+AH17,"") | AJ17: =IFERROR(VLOOKUP(AI17,'Helper(IMPORTANT!)'!$AX$1:$AY$41,2,TRUE),"")
A18: 6 | B18: ='INPUT DATA'!B18 | P18: =IF(COUNT($F18:$O18)=0,"",SUM($F18:$O18)) | Q18: =IFERROR(IF(P18="","",ROUND(P18/$P$11*100,2)),"") | R18: =IFERROR(IF(Q18="","",ROUND(Q18*$R$11,2)),"") | AC18: =IF(COUNT($S18:$AB18)=0,"",SUM($S18:$AB18)) | AD18: =IFERROR(IF(AC18="","",ROUND(AC18/$AC$11*100,2)),"") | AE18: =IFERROR(IF(AD18="","",ROUND(AD18*$AE$11,2)),"") | AG18: =IFERROR(IF(AF18="","",ROUND(AF18/$AF$11*100,2)),"") | AH18: =IFERROR(IF(AG18="","",ROUND(AG18*$AH$11,2)),"") | AI18: =IFERROR(R18+AE18+AH18,"") | AJ18: =IFERROR(VLOOKUP(AI18,'Helper(IMPORTANT!)'!$AX$1:$AY$41,2,TRUE),"")
A19: 7 | B19: ='INPUT DATA'!B19 | P19: =IF(COUNT($F19:$O19)=0,"",SUM($F19:$O19)) | Q19: =IFERROR(IF(P19="","",ROUND(P19/$P$11*100,2)),"") | R19: =IFERROR(IF(Q19="","",ROUND(Q19*$R$11,2)),"") | AC19: =IF(COUNT($S19:$AB19)=0,"",SUM($S19:$AB19)) | AD19: =IFERROR(IF(AC19="","",ROUND(AC19/$AC$11*100,2)),"") | AE19: =IFERROR(IF(AD19="","",ROUND(AD19*$AE$11,2)),"") | AG19: =IFERROR(IF(AF19="","",ROUND(AF19/$AF$11*100,2)),"") | AH19: =IFERROR(IF(AG19="","",ROUND(AG19*$AH$11,2)),"") | AI19: =IFERROR(R19+AE19+AH19,"") | AJ19: =IFERROR(VLOOKUP(AI19,'Helper(IMPORTANT!)'!$AX$1:$AY$41,2,TRUE),"")
A20: 8 | B20: ='INPUT DATA'!B20 | P20: =IF(COUNT($F20:$O20)=0,"",SUM($F20:$O20)) | Q20: =IFERROR(IF(P20="","",ROUND(P20/$P$11*100,2)),"") | R20: =IFERROR(IF(Q20="","",ROUND(Q20*$R$11,2)),"") | AC20: =IF(COUNT($S20:$AB20)=0,"",SUM($S20:$AB20)) | AD20: =IFERROR(IF(AC20="","",ROUND(AC20/$AC$11*100,2)),"") | AE20: =IFERROR(IF(AD20="","",ROUND(AD20*$AE$11,2)),"") | AG20: =IFERROR(IF(AF20="","",ROUND(AF20/$AF$11*100,2)),"") | AH20: =IFERROR(IF(AG20="","",ROUND(AG20*$AH$11,2)),"") | AI20: =IFERROR(R20+AE20+AH20,"") | AJ20: =IFERROR(VLOOKUP(AI20,'Helper(IMPORTANT!)'!$AX$1:$AY$41,2,TRUE),"")
A21: 9 | B21: ='INPUT DATA'!B21 | P21: =IF(COUNT($F21:$O21)=0,"",SUM($F21:$O21)) | Q21: =IFERROR(IF(P21="","",ROUND(P21/$P$11*100,2)),"") | R21: =IFERROR(IF(Q21="","",ROUND(Q21*$R$11,2)),"") | AC21: =IF(COUNT($S21:$AB21)=0,"",SUM($S21:$AB21)) | AD21: =IFERROR(IF(AC21="","",ROUND(AC21/$AC$11*100,2)),"") | AE21: =IFERROR(IF(AD21="","",ROUND(AD21*$AE$11,2)),"") | AG21: =IFERROR(IF(AF21="","",ROUND(AF21/$AF$11*100,2)),"") | AH21: =IFERROR(IF(AG21="","",ROUND(AG21*$AH$11,2)),"") | AI21: =IFERROR(R21+AE21+AH21,"") | AJ21: =IFERROR(VLOOKUP(AI21,'Helper(IMPORTANT!)'!$AX$1:$AY$41,2,TRUE),"")
A22: 10 | B22: ='INPUT DATA'!B22 | P22: =IF(COUNT($F22:$O22)=0,"",SUM($F22:$O22)) | Q22: =IFERROR(IF(P22="","",ROUND(P22/$P$11*100,2)),"") | R22: =IFERROR(IF(Q22="","",ROUND(Q22*$R$11,2)),"") | AC22: =IF(COUNT($S22:$AB22)=0,"",SUM($S22:$AB22)) | AD22: =IFERROR(IF(AC22="","",ROUND(AC22/$AC$11*100,2)),"") | AE22: =IFERROR(IF(AD22="","",ROUND(AD22*$AE$11,2)),"") | AG22: =IFERROR(IF(AF22="","",ROUND(AF22/$AF$11*100,2)),"") | AH22: =IFERROR(IF(AG22="","",ROUND(AG22*$AH$11,2)),"") | AI22: =IFERROR(R22+AE22+AH22,"") | AJ22: =IFERROR(VLOOKUP(AI22,'Helper(IMPORTANT!)'!$AX$1:$AY$41,2,TRUE),"")
A23: 11 | B23: ='INPUT DATA'!B23 | P23: =IF(COUNT($F23:$O23)=0,"",SUM($F23:$O23)) | Q23: =IFERROR(IF(P23="","",ROUND(P23/$P$11*100,2)),"") | R23: =IFERROR(IF(Q23="","",ROUND(Q23*$R$11,2)),"") | AC23: =IF(COUNT($S23:$AB23)=0,"",SUM($S23:$AB23)) | AD23: =IFERROR(IF(AC23="","",ROUND(AC23/$AC$11*100,2)),"") | AE23: =IFERROR(IF(AD23="","",ROUND(AD23*$AE$11,2)),"") | AG23: =IFERROR(IF(AF23="","",ROUND(AF23/$AF$11*100,2)),"") | AH23: =IFERROR(IF(AG23="","",ROUND(AG23*$AH$11,2)),"") | AI23: =IFERROR(R23+AE23+AH23,"") | AJ23: =IFERROR(VLOOKUP(AI23,'Helper(IMPORTANT!)'!$AX$1:$AY$41,2,TRUE),"")
A24: 12 | B24: ='INPUT DATA'!B24 | P24: =IF(COUNT($F24:$O24)=0,"",SUM($F24:$O24)) | Q24: =IFERROR(IF(P24="","",ROUND(P24/$P$11*100,2)),"") | R24: =IFERROR(IF(Q24="","",ROUND(Q24*$R$11,2)),"") | AC24: =IF(COUNT($S24:$AB24)=0,"",SUM($S24:$AB24)) | AD24: =IFERROR(IF(AC24="","",ROUND(AC24/$AC$11*100,2)),"") | AE24: =IFERROR(IF(AD24="","",ROUND(AD24*$AE$11,2)),"") | AG24: =IFERROR(IF(AF24="","",ROUND(AF24/$AF$11*100,2)),"") | AH24: =IFERROR(IF(AG24="","",ROUND(AG24*$AH$11,2)),"") | AI24: =IFERROR(R24+AE24+AH24,"") | AJ24: =IFERROR(VLOOKUP(AI24,'Helper(IMPORTANT!)'!$AX$1:$AY$41,2,TRUE),"")
... A62: 50 | B62: ='INPUT DATA'!B62 | P62: =IF(COUNT($F62:$O62)=0,"",SUM($F62:$O62)) | Q62: =IFERROR(IF(P62="","",ROUND(P62/$P$11*100,2)),"") | R62: =IFERROR(IF(Q62="","",ROUND(Q62*$R$11,2)),"") | AC62: =IF(COUNT($S62:$AB62)=0,"",SUM($S62:$AB62)) | AD62: =IFERROR(IF(AC62="","",ROUND(AC62/$AC$11*100,2)),"") | AE62: =IFERROR(IF(AD62="","",ROUND(AD62*$AE$11,2)),"") | AG62: =IFERROR(IF(AF62="","",ROUND(AF62/$AF$11*100,2)),"") | AH62: =IFERROR(IF(AG62="","",ROUND(AG62*$AH$11,2)),"") | AI62: =IFERROR(R62+AE62+AH62,"") | AJ62: =IFERROR(VLOOKUP(AI62,'Helper(IMPORTANT!)'!$AX$1:$AY$41,2,TRUE),"")
A63: FEMALE
A64: 1 | B64: ='INPUT DATA'!B64 | P64: =IF(COUNT($F64:$O64)=0,"",SUM($F64:$O64)) | Q64: =IFERROR(IF(P64="","",ROUND(P64/$P$11*100,2)),"") | R64: =IFERROR(IF(Q64="","",ROUND(Q64*$R$11,2)),"") | AC64: =IF(COUNT($S64:$AB64)=0,"",SUM($S64:$AB64)) | AD64: =IFERROR(IF(AC64="","",ROUND(AC64/$AC$11*100,2)),"") | AE64: =IFERROR(IF(AD64="","",ROUND(AD64*$AE$11,2)),"") | AG64: =IFERROR(IF(AF64="","",ROUND(AF64/$AF$11*100,2)),"") | AH64: =IFERROR(IF(AG64="","",ROUND(AG64*$AH$11,2)),"") | AI64: =IFERROR(R64+AE64+AH64,"") | AJ64: =IFERROR(VLOOKUP(AI64,'Helper(IMPORTANT!)'!$AX$1:$AY$41,2,TRUE),"")
A65: 2 | B65: ='INPUT DATA'!B65 | P65: =IF(COUNT($F65:$O65)=0,"",SUM($F65:$O65)) | Q65: =IFERROR(IF(P65="","",ROUND(P65/$P$11*100,2)),"") | R65: =IFERROR(IF(Q65="","",ROUND(Q65*$R$11,2)),"") | AC65: =IF(COUNT($S65:$AB65)=0,"",SUM($S65:$AB65)) | AD65: =IFERROR(IF(AC65="","",ROUND(AC65/$AC$11*100,2)),"") | AE65: =IFERROR(IF(AD65="","",ROUND(AD65*$AE$11,2)),"") | AG65: =IFERROR(IF(AF65="","",ROUND(AF65/$AF$11*100,2)),"") | AH65: =IFERROR(IF(AG65="","",ROUND(AG65*$AH$11,2)),"") | AI65: =IFERROR(R65+AE65+AH65,"") | AJ65: =IFERROR(VLOOKUP(AI65,'Helper(IMPORTANT!)'!$AX$1:$AY$41,2,TRUE),"")
A66: 3 | B66: ='INPUT DATA'!B66 | P66: =IF(COUNT($F66:$O66)=0,"",SUM($F66:$O66)) | Q66: =IFERROR(IF(P66="","",ROUND(P66/$P$11*100,2)),"") | R66: =IFERROR(IF(Q66="","",ROUND(Q66*$R$11,2)),"") | AC66: =IF(COUNT($S66:$AB66)=0,"",SUM($S66:$AB66)) | AD66: =IFERROR(IF(AC66="","",ROUND(AC66/$AC$11*100,2)),"") | AE66: =IFERROR(IF(AD66="","",ROUND(AD66*$AE$11,2)),"") | AG66: =IFERROR(IF(AF66="","",ROUND(AF66/$AF$11*100,2)),"") | AH66: =IFERROR(IF(AG66="","",ROUND(AG66*$AH$11,2)),"") | AI66: =IFERROR(R66+AE66+AH66,"") | AJ66: =IFERROR(VLOOKUP(AI66,'Helper(IMPORTANT!)'!$AX$1:$AY$41,2,TRUE),"")
A67: 4 | B67: ='INPUT DATA'!B67 | P67: =IF(COUNT($F67:$O67)=0,"",SUM($F67:$O67)) | Q67: =IFERROR(IF(P67="","",ROUND(P67/$P$11*100,2)),"") | R67: =IFERROR(IF(Q67="","",ROUND(Q67*$R$11,2)),"") | AC67: =IF(COUNT($S67:$AB67)=0,"",SUM($S67:$AB67)) | AD67: =IFERROR(IF(AC67="","",ROUND(AC67/$AC$11*100,2)),"") | AE67: =IFERROR(IF(AD67="","",ROUND(AD67*$AE$11,2)),"") | AG67: =IFERROR(IF(AF67="","",ROUND(AF67/$AF$11*100,2)),"") | AH67: =IFERROR(IF(AG67="","",ROUND(AG67*$AH$11,2)),"") | AI67: =IFERROR(R67+AE67+AH67,"") | AJ67: =IFERROR(VLOOKUP(AI67,'Helper(IMPORTANT!)'!$AX$1:$AY$41,2,TRUE),"")
A68: 5 | B68: ='INPUT DATA'!B68 | P68: =IF(COUNT($F68:$O68)=0,"",SUM($F68:$O68)) | Q68: =IFERROR(IF(P68="","",ROUND(P68/$P$11*100,2)),"") | R68: =IFERROR(IF(Q68="","",ROUND(Q68*$R$11,2)),"") | AC68: =IF(COUNT($S68:$AB68)=0,"",SUM($S68:$AB68)) | AD68: =IFERROR(IF(AC68="","",ROUND(AC68/$AC$11*100,2)),"") | AE68: =IFERROR(IF(AD68="","",ROUND(AD68*$AE$11,2)),"") | AG68: =IFERROR(IF(AF68="","",ROUND(AF68/$AF$11*100,2)),"") | AH68: =IFERROR(IF(AG68="","",ROUND(AG68*$AH$11,2)),"") | AI68: =IFERROR(R68+AE68+AH68,"") | AJ68: =IFERROR(VLOOKUP(AI68,'Helper(IMPORTANT!)'!$AX$1:$AY$41,2,TRUE),"")
A69: 6 | B69: ='INPUT DATA'!B69 | P69: =IF(COUNT($F69:$O69)=0,"",SUM($F69:$O69)) | Q69: =IFERROR(IF(P69="","",ROUND(P69/$P$11*100,2)),"") | R69: =IFERROR(IF(Q69="","",ROUND(Q69*$R$11,2)),"") | AC69: =IF(COUNT($S69:$AB69)=0,"",SUM($S69:$AB69)) | AD69: =IFERROR(IF(AC69="","",ROUND(AC69/$AC$11*100,2)),"") | AE69: =IFERROR(IF(AD69="","",ROUND(AD69*$AE$11,2)),"") | AG69: =IFERROR(IF(AF69="","",ROUND(AF69/$AF$11*100,2)),"") | AH69: =IFERROR(IF(AG69="","",ROUND(AG69*$AH$11,2)),"") | AI69: =IFERROR(R69+AE69+AH69,"") | AJ69: =IFERROR(VLOOKUP(AI69,'Helper(IMPORTANT!)'!$AX$1:$AY$41,2,TRUE),"")
A70: 7 | B70: ='INPUT DATA'!B70 | P70: =IF(COUNT($F70:$O70)=0,"",SUM($F70:$O70)) | Q70: =IFERROR(IF(P70="","",ROUND(P70/$P$11*100,2)),"") | R70: =IFERROR(IF(Q70="","",ROUND(Q70*$R$11,2)),"") | AC70: =IF(COUNT($S70:$AB70)=0,"",SUM($S70:$AB70)) | AD70: =IFERROR(IF(AC70="","",ROUND(AC70/$AC$11*100,2)),"") | AE70: =IFERROR(IF(AD70="","",ROUND(AD70*$AE$11,2)),"") | AG70: =IFERROR(IF(AF70="","",ROUND(AF70/$AF$11*100,2)),"") | AH70: =IFERROR(IF(AG70="","",ROUND(AG70*$AH$11,2)),"") | AI70: =IFERROR(R70+AE70+AH70,"") | AJ70: =IFERROR(VLOOKUP(AI70,'Helper(IMPORTANT!)'!$AX$1:$AY$41,2,TRUE),"")
A71: 8 | B71: ='INPUT DATA'!B71 | P71: =IF(COUNT($F71:$O71)=0,"",SUM($F71:$O71)) | Q71: =IFERROR(IF(P71="","",ROUND(P71/$P$11*100,2)),"") | R71: =IFERROR(IF(Q71="","",ROUND(Q71*$R$11,2)),"") | AC71: =IF(COUNT($S71:$AB71)=0,"",SUM($S71:$AB71)) | AD71: =IFERROR(IF(AC71="","",ROUND(AC71/$AC$11*100,2)),"") | AE71: =IFERROR(IF(AD71="","",ROUND(AD71*$AE$11,2)),"") | AG71: =IFERROR(IF(AF71="","",ROUND(AF71/$AF$11*100,2)),"") | AH71: =IFERROR(IF(AG71="","",ROUND(AG71*$AH$11,2)),"") | AI71: =IFERROR(R71+AE71+AH71,"") | AJ71: =IFERROR(VLOOKUP(AI71,'Helper(IMPORTANT!)'!$AX$1:$AY$41,2,TRUE),"")
A72: 9 | B72: ='INPUT DATA'!B72 | P72: =IF(COUNT($F72:$O72)=0,"",SUM($F72:$O72)) | Q72: =IFERROR(IF(P72="","",ROUND(P72/$P$11*100,2)),"") | R72: =IFERROR(IF(Q72="","",ROUND(Q72*$R$11,2)),"") | AC72: =IF(COUNT($S72:$AB72)=0,"",SUM($S72:$AB72)) | AD72: =IFERROR(IF(AC72="","",ROUND(AC72/$AC$11*100,2)),"") | AE72: =IFERROR(IF(AD72="","",ROUND(AD72*$AE$11,2)),"") | AG72: =IFERROR(IF(AF72="","",ROUND(AF72/$AF$11*100,2)),"") | AH72: =IFERROR(IF(AG72="","",ROUND(AG72*$AH$11,2)),"") | AI72: =IFERROR(R72+AE72+AH72,"") | AJ72: =IFERROR(VLOOKUP(AI72,'Helper(IMPORTANT!)'!$AX$1:$AY$41,2,TRUE),"")
A73: 10 | B73: ='INPUT DATA'!B73 | P73: =IF(COUNT($F73:$O73)=0,"",SUM($F73:$O73)) | Q73: =IFERROR(IF(P73="","",ROUND(P73/$P$11*100,2)),"") | R73: =IFERROR(IF(Q73="","",ROUND(Q73*$R$11,2)),"") | AC73: =IF(COUNT($S73:$AB73)=0,"",SUM($S73:$AB73)) | AD73: =IFERROR(IF(AC73="","",ROUND(AC73/$AC$11*100,2)),"") | AE73: =IFERROR(IF(AD73="","",ROUND(AD73*$AE$11,2)),"") | AG73: =IFERROR(IF(AF73="","",ROUND(AF73/$AF$11*100,2)),"") | AH73: =IFERROR(IF(AG73="","",ROUND(AG73*$AH$11,2)),"") | AI73: =IFERROR(R73+AE73+AH73,"") | AJ73: =IFERROR(VLOOKUP(AI73,'Helper(IMPORTANT!)'!$AX$1:$AY$41,2,TRUE),"")
A74: 11 | B74: ='INPUT DATA'!B74 | P74: =IF(COUNT($F74:$O74)=0,"",SUM($F74:$O74)) | Q74: =IFERROR(IF(P74="","",ROUND(P74/$P$11*100,2)),"") | R74: =IFERROR(IF(Q74="","",ROUND(Q74*$R$11,2)),"") | AC74: =IF(COUNT($S74:$AB74)=0,"",SUM($S74:$AB74)) | AD74: =IFERROR(IF(AC74="","",ROUND(AC74/$AC$11*100,2)),"") | AE74: =IFERROR(IF(AD74="","",ROUND(AD74*$AE$11,2)),"") | AG74: =IFERROR(IF(AF74="","",ROUND(AF74/$AF$11*100,2)),"") | AH74: =IFERROR(IF(AG74="","",ROUND(AG74*$AH$11,2)),"") | AI74: =IFERROR(R74+AE74+AH74,"") | AJ74: =IFERROR(VLOOKUP(AI74,'Helper(IMPORTANT!)'!$AX$1:$AY$41,2,TRUE),"")
A75: 12 | B75: ='INPUT DATA'!B75 | P75: =IF(COUNT($F75:$O75)=0,"",SUM($F75:$O75)) | Q75: =IFERROR(IF(P75="","",ROUND(P75/$P$11*100,2)),"") | R75: =IFERROR(IF(Q75="","",ROUND(Q75*$R$11,2)),"") | AC75: =IF(COUNT($S75:$AB75)=0,"",SUM($S75:$AB75)) | AD75: =IFERROR(IF(AC75="","",ROUND(AC75/$AC$11*100,2)),"") | AE75: =IFERROR(IF(AD75="","",ROUND(AD75*$AE$11,2)),"") | AG75: =IFERROR(IF(AF75="","",ROUND(AF75/$AF$11*100,2)),"") | AH75: =IFERROR(IF(AG75="","",ROUND(AG75*$AH$11,2)),"") | AI75: =IFERROR(R75+AE75+AH75,"") | AJ75: =IFERROR(VLOOKUP(AI75,'Helper(IMPORTANT!)'!$AX$1:$AY$41,2,TRUE),"")
... A113: 50 | B113: ='INPUT DATA'!B113 | P113: =IF(COUNT($F113:$O113)=0,"",SUM($F113:$O113)) | Q113: =IFERROR(IF(P113="","",ROUND(P113/$P$11*100,2)),"") | R113: =IFERROR(IF(Q113="","",ROUND(Q113*$R$11,2)),"") | AC113: =IF(COUNT($S113:$AB113)=0,"",SUM($S113:$AB113)) | AD113: =IFERROR(IF(AC113="","",ROUND(AC113/$AC$11*100,2)),"") | AE113: =IFERROR(IF(AD113="","",ROUND(AD113*$AE$11,2)),"") | AG113: =IFERROR(IF(AF113="","",ROUND(AF113/$AF$11*100,2)),"") | AH113: =IFERROR(IF(AG113="","",ROUND(AG113*$AH$11,2)),"") | AI113: =IFERROR(R113+AE113+AH113,"") | AJ113: =IFERROR(VLOOKUP(AI113,'Helper(IMPORTANT!)'!$AX$1:$AY$41,2,TRUE),"")

Sheet 2ND
A1: Senior High School Class Record
A3: (Pursuant to Deped Order 8 series of 2015)
C4: REGION | G4: ='INPUT DATA'!G4 | L4: DIVISION | O4: ='INPUT DATA'!O4
B5: SCHOOL NAME | G5: ='INPUT DATA'!G5 | T5: SCHOOL ID | X5: ='INPUT DATA'!$X$5 | AD5: SCHOOL YEAR | AG5: ='INPUT DATA'!AG5
A7: =IF('INPUT DATA'!S8="","",IF('INPUT DATA'!S8="1ST","SECOND QUARTER",IF('INPUT DATA'!S8="2ND","FOURTH QUARTER"))) | F7: GRADE & SECTION: | K7: ='INPUT DATA'!K7 | Q7: TEACHER: | S7: ='INPUT DATA'!S7 | AC7: SUBJECT: | AE7: ='INPUT DATA'!AE7
Q8: SEMESTER: | S8: ='INPUT DATA'!S8 | AC8: TRACK: | AE8: ='INPUT DATA'!AE8
A9: LEARNERS' NAMES | F9: =IF('INPUT DATA'!AE8="","",INDEX('Helper(IMPORTANT!)'!$AR$2:$AR$5,MATCH(AE8,'Helper(IMPORTANT!)'!$AQ$2:$AQ$5,0))) | S9: =IF('INPUT DATA'!AE8="","",INDEX('Helper(IMPORTANT!)'!$AS$2:$AS$5,MATCH(AE8,'Helper(IMPORTANT!)'!$AQ$2:$AQ$5,0))) | AF9: =IF('INPUT DATA'!AE8="","",INDEX('Helper(IMPORTANT!)'!$AT$2:$AT$5,MATCH(AE8,'Helper(IMPORTANT!)'!$AQ$2:$AQ$5,0))) | AI9: Initial Grade | AJ9: Quarterly Grade
F10: 1 | G10: 2 | H10: 3 | I10: 4 | J10: 5 | K10: 6 | L10: 7 | M10: 8 | N10: 9 | O10: 10 | P10: Total | Q10: PS | R10: WS | S10: 1 | T10: 2 | U10: 3 | V10: 4 | W10: 5 | X10: 6 | Y10: 7 | Z10: 8 | AA10: 9 | AB10: 10 | AC10: Total | AD10: PS | AE10: WS | AF10: 1 | AG10: PS | AH10: WS
A11: HIGHEST POSSIBLE SCORE | P11: =IF(COUNT($F11:$O11)=0,"",SUM($F11:$O11)) | Q11: 100 | R11: =IF('INPUT DATA'!AE8="","",INDEX('Helper(IMPORTANT!)'!$AU$2:$AU$5,MATCH(AE8,'Helper(IMPORTANT!)'!$AQ$2:$AQ$5,0))) | AC11: =IF(COUNT($S11:$AB11)=0,"",SUM($S11:$AB11)) | AD11: 100 | AE11: =IF('INPUT DATA'!AE8="","",INDEX('Helper(IMPORTANT!)'!$AV$2:$AV$5,MATCH(AE8,'Helper(IMPORTANT!)'!$AQ$2:$AQ$5,0))) | AG11: 100 | AH11: =IF('INPUT DATA'!AE8="","",INDEX('Helper(IMPORTANT!)'!$AW$2:$AW$5,MATCH(AE8,'Helper(IMPORTANT!)'!$AQ$2:$AQ$5,0)))
A12: MALE
A13: 1 | B13: ='INPUT DATA'!B13 | P13: =IF(COUNT($F13:$O13)=0,"",SUM($F13:$O13)) | Q13: =IFERROR(IF(P13="","",ROUND(P13/$P$11*100,2)),"") | R13: =IFERROR(IF(Q13="","",ROUND(Q13*$R$11,2)),"") | AC13: =IF(COUNT($S13:$AB13)=0,"",SUM($S13:$AB13)) | AD13: =IFERROR(IF(AC13="","",ROUND(AC13/$AC$11*100,2)),"") | AE13: =IFERROR(IF(AD13="","",ROUND(AD13*$AE$11,2)),"") | AG13: =IFERROR(IF(AF13="","",ROUND(AF13/$AF$11*100,2)),"") | AH13: =IFERROR(IF(AG13="","",ROUND(AG13*$AH$11,2)),"") | AI13: =IFERROR(R13+AE13+AH13,"") | AJ13: =IFERROR(VLOOKUP(AI13,'Helper(IMPORTANT!)'!$AX$1:$AY$41,2,TRUE),"")
A14: 2 | B14: ='INPUT DATA'!B14 | P14: =IF(COUNT($F14:$O14)=0,"",SUM($F14:$O14)) | Q14: =IFERROR(IF(P14="","",ROUND(P14/$P$11*100,2)),"") | R14: =IFERROR(IF(Q14="","",ROUND(Q14*$R$11,2)),"") | AC14: =IF(COUNT($S14:$AB14)=0,"",SUM($S14:$AB14)) | AD14: =IFERROR(IF(AC14="","",ROUND(AC14/$AC$11*100,2)),"") | AE14: =IFERROR(IF(AD14="","",ROUND(AD14*$AE$11,2)),"") | AG14: =IFERROR(IF(AF14="","",ROUND(AF14/$AF$11*100,2)),"") | AH14: =IFERROR(IF(AG14="","",ROUND(AG14*$AH$11,2)),"") | AI14: =IFERROR(R14+AE14+AH14,"") | AJ14: =IFERROR(VLOOKUP(AI14,'Helper(IMPORTANT!)'!$AX$1:$AY$41,2,TRUE),"")
A15: 3 | B15: ='INPUT DATA'!B15 | P15: =IF(COUNT($F15:$O15)=0,"",SUM($F15:$O15)) | Q15: =IFERROR(IF(P15="","",ROUND(P15/$P$11*100,2)),"") | R15: =IFERROR(IF(Q15="","",ROUND(Q15*$R$11,2)),"") | AC15: =IF(COUNT($S15:$AB15)=0,"",SUM($S15:$AB15)) | AD15: =IFERROR(IF(AC15="","",ROUND(AC15/$AC$11*100,2)),"") | AE15: =IFERROR(IF(AD15="","",ROUND(AD15*$AE$11,2)),"") | AG15: =IFERROR(IF(AF15="","",ROUND(AF15/$AF$11*100,2)),"") | AH15: =IFERROR(IF(AG15="","",ROUND(AG15*$AH$11,2)),"") | AI15: =IFERROR(R15+AE15+AH15,"") | AJ15: =IFERROR(VLOOKUP(AI15,'Helper(IMPORTANT!)'!$AX$1:$AY$41,2,TRUE),"")
A16: 4 | B16: ='INPUT DATA'!B16 | P16: =IF(COUNT($F16:$O16)=0,"",SUM($F16:$O16)) | Q16: =IFERROR(IF(P16="","",ROUND(P16/$P$11*100,2)),"") | R16: =IFERROR(IF(Q16="","",ROUND(Q16*$R$11,2)),"") | AC16: =IF(COUNT($S16:$AB16)=0,"",SUM($S16:$AB16)) | AD16: =IFERROR(IF(AC16="","",ROUND(AC16/$AC$11*100,2)),"") | AE16: =IFERROR(IF(AD16="","",ROUND(AD16*$AE$11,2)),"") | AG16: =IFERROR(IF(AF16="","",ROUND(AF16/$AF$11*100,2)),"") | AH16: =IFERROR(IF(AG16="","",ROUND(AG16*$AH$11,2)),"") | AI16: =IFERROR(R16+AE16+AH16,"") | AJ16: =IFERROR(VLOOKUP(AI16,'Helper(IMPORTANT!)'!$AX$1:$AY$41,2,TRUE),"")
A17: 5 | B17: ='INPUT DATA'!B17 | P17: =IF(COUNT($F17:$O17)=0,"",SUM($F17:$O17)) | Q17: =IFERROR(IF(P17="","",ROUND(P17/$P$11*100,2)),"") | R17: =IFERROR(IF(Q17="","",ROUND(Q17*$R$11,2)),"") | AC17: =IF(COUNT($S17:$AB17)=0,"",SUM($S17:$AB17)) | AD17: =IFERROR(IF(AC17="","",ROUND(AC17/$AC$11*100,2)),"") | AE17: =IFERROR(IF(AD17="","",ROUND(AD17*$AE$11,2)),"") | AG17: =IFERROR(IF(AF17="","",ROUND(AF17/$AF$11*100,2)),"") | AH17: =IFERROR(IF(AG17="","",ROUND(AG17*$AH$11,2)),"") | AI17: =IFERROR(R17+AE17+AH17,"") | AJ17: =IFERROR(VLOOKUP(AI17,'Helper(IMPORTANT!)'!$AX$1:$AY$41,2,TRUE),"")
A18: 6 | B18: ='INPUT DATA'!B18 | P18: =IF(COUNT($F18:$O18)=0,"",SUM($F18:$O18)) | Q18: =IFERROR(IF(P18="","",ROUND(P18/$P$11*100,2)),"") | R18: =IFERROR(IF(Q18="","",ROUND(Q18*$R$11,2)),"") | AC18: =IF(COUNT($S18:$AB18)=0,"",SUM($S18:$AB18)) | AD18: =IFERROR(IF(AC18="","",ROUND(AC18/$AC$11*100,2)),"") | AE18: =IFERROR(IF(AD18="","",ROUND(AD18*$AE$11,2)),"") | AG18: =IFERROR(IF(AF18="","",ROUND(AF18/$AF$11*100,2)),"") | AH18: =IFERROR(IF(AG18="","",ROUND(AG18*$AH$11,2)),"") | AI18: =IFERROR(R18+AE18+AH18,"") | AJ18: =IFERROR(VLOOKUP(AI18,'Helper(IMPORTANT!)'!$AX$1:$AY$41,2,TRUE),"")
A19: 7 | B19: ='INPUT DATA'!B19 | P19: =IF(COUNT($F19:$O19)=0,"",SUM($F19:$O19)) | Q19: =IFERROR(IF(P19="","",ROUND(P19/$P$11*100,2)),"") | R19: =IFERROR(IF(Q19="","",ROUND(Q19*$R$11,2)),"") | AC19: =IF(COUNT($S19:$AB19)=0,"",SUM($S19:$AB19)) | AD19: =IFERROR(IF(AC19="","",ROUND(AC19/$AC$11*100,2)),"") | AE19: =IFERROR(IF(AD19="","",ROUND(AD19*$AE$11,2)),"") | AG19: =IFERROR(IF(AF19="","",ROUND(AF19/$AF$11*100,2)),"") | AH19: =IFERROR(IF(AG19="","",ROUND(AG19*$AH$11,2)),"") | AI19: =IFERROR(R19+AE19+AH19,"") | AJ19: =IFERROR(VLOOKUP(AI19,'Helper(IMPORTANT!)'!$AX$1:$AY$41,2,TRUE),"")
A20: 8 | B20: ='INPUT DATA'!B20 | P20: =IF(COUNT($F20:$O20)=0,"",SUM($F20:$O20)) | Q20: =IFERROR(IF(P20="","",ROUND(P20/$P$11*100,2)),"") | R20: =IFERROR(IF(Q20="","",ROUND(Q20*$R$11,2)),"") | AC20: =IF(COUNT($S20:$AB20)=0,"",SUM($S20:$AB20)) | AD20: =IFERROR(IF(AC20="","",ROUND(AC20/$AC$11*100,2)),"") | AE20: =IFERROR(IF(AD20="","",ROUND(AD20*$AE$11,2)),"") | AG20: =IFERROR(IF(AF20="","",ROUND(AF20/$AF$11*100,2)),"") | AH20: =IFERROR(IF(AG20="","",ROUND(AG20*$AH$11,2)),"") | AI20: =IFERROR(R20+AE20+AH20,"") | AJ20: =IFERROR(VLOOKUP(AI20,'Helper(IMPORTANT!)'!$AX$1:$AY$41,2,TRUE),"")
A21: 9 | B21: ='INPUT DATA'!B21 | P21: =IF(COUNT($F21:$O21)=0,"",SUM($F21:$O21)) | Q21: =IFERROR(IF(P21="","",ROUND(P21/$P$11*100,2)),"") | R21: =IFERROR(IF(Q21="","",ROUND(Q21*$R$11,2)),"") | AC21: =IF(COUNT($S21:$AB21)=0,"",SUM($S21:$AB21)) | AD21: =IFERROR(IF(AC21="","",ROUND(AC21/$AC$11*100,2)),"") | AE21: =IFERROR(IF(AD21="","",ROUND(AD21*$AE$11,2)),"") | AG21: =IFERROR(IF(AF21="","",ROUND(AF21/$AF$11*100,2)),"") | AH21: =IFERROR(IF(AG21="","",ROUND(AG21*$AH$11,2)),"") | AI21: =IFERROR(R21+AE21+AH21,"") | AJ21: =IFERROR(VLOOKUP(AI21,'Helper(IMPORTANT!)'!$AX$1:$AY$41,2,TRUE),"")
A22: 10 | B22: ='INPUT DATA'!B22 | P22: =IF(COUNT($F22:$O22)=0,"",SUM($F22:$O22)) | Q22: =IFERROR(IF(P22="","",ROUND(P22/$P$11*100,2)),"") | R22: =IFERROR(IF(Q22="","",ROUND(Q22*$R$11,2)),"") | AC22: =IF(COUNT($S22:$AB22)=0,"",SUM($S22:$AB22)) | AD22: =IFERROR(IF(AC22="","",ROUND(AC22/$AC$11*100,2)),"") | AE22: =IFERROR(IF(AD22="","",ROUND(AD22*$AE$11,2)),"") | AG22: =IFERROR(IF(AF22="","",ROUND(AF22/$AF$11*100,2)),"") | AH22: =IFERROR(IF(AG22="","",ROUND(AG22*$AH$11,2)),"") | AI22: =IFERROR(R22+AE22+AH22,"") | AJ22: =IFERROR(VLOOKUP(AI22,'Helper(IMPORTANT!)'!$AX$1:$AY$41,2,TRUE),"")
A23: 11 | B23: ='INPUT DATA'!B23 | P23: =IF(COUNT($F23:$O23)=0,"",SUM($F23:$O23)) | Q23: =IFERROR(IF(P23="","",ROUND(P23/$P$11*100,2)),"") | R23: =IFERROR(IF(Q23="","",ROUND(Q23*$R$11,2)),"") | AC23: =IF(COUNT($S23:$AB23)=0,"",SUM($S23:$AB23)) | AD23: =IFERROR(IF(AC23="","",ROUND(AC23/$AC$11*100,2)),"") | AE23: =IFERROR(IF(AD23="","",ROUND(AD23*$AE$11,2)),"") | AG23: =IFERROR(IF(AF23="","",ROUND(AF23/$AF$11*100,2)),"") | AH23: =IFERROR(IF(AG23="","",ROUND(AG23*$AH$11,2)),"") | AI23: =IFERROR(R23+AE23+AH23,"") | AJ23: =IFERROR(VLOOKUP(AI23,'Helper(IMPORTANT!)'!$AX$1:$AY$41,2,TRUE),"")
A24: 12 | B24: ='INPUT DATA'!B24 | P24: =IF(COUNT($F24:$O24)=0,"",SUM($F24:$O24)) | Q24: =IFERROR(IF(P24="","",ROUND(P24/$P$11*100,2)),"") | R24: =IFERROR(IF(Q24="","",ROUND(Q24*$R$11,2)),"") | AC24: =IF(COUNT($S24:$AB24)=0,"",SUM($S24:$AB24)) | AD24: =IFERROR(IF(AC24="","",ROUND(AC24/$AC$11*100,2)),"") | AE24: =IFERROR(IF(AD24="","",ROUND(AD24*$AE$11,2)),"") | AG24: =IFERROR(IF(AF24="","",ROUND(AF24/$AF$11*100,2)),"") | AH24: =IFERROR(IF(AG24="","",ROUND(AG24*$AH$11,2)),"") | AI24: =IFERROR(R24+AE24+AH24,"") | AJ24: =IFERROR(VLOOKUP(AI24,'Helper(IMPORTANT!)'!$AX$1:$AY$41,2,TRUE),"")
... A62: 50 | B62: ='INPUT DATA'!B62 | P62: =IF(COUNT($F62:$O62)=0,"",SUM($F62:$O62)) | Q62: =IFERROR(IF(P62="","",ROUND(P62/$P$11*100,2)),"") | R62: =IFERROR(IF(Q62="","",ROUND(Q62*$R$11,2)),"") | AC62: =IF(COUNT($S62:$AB62)=0,"",SUM($S62:$AB62)) | AD62: =IFERROR(IF(AC62="","",ROUND(AC62/$AC$11*100,2)),"") | AE62: =IFERROR(IF(AD62="","",ROUND(AD62*$AE$11,2)),"") | AG62: =IFERROR(IF(AF62="","",ROUND(AF62/$AF$11*100,2)),"") | AH62: =IFERROR(IF(AG62="","",ROUND(AG62*$AH$11,2)),"") | AI62: =IFERROR(R62+AE62+AH62,"") | AJ62: =IFERROR(VLOOKUP(AI62,'Helper(IMPORTANT!)'!$AX$1:$AY$41,2,TRUE),"")
A63: FEMALE
A64: 1 | B64: ='INPUT DATA'!B64 | P64: =IF(COUNT($F64:$O64)=0,"",SUM($F64:$O64)) | Q64: =IFERROR(IF(P64="","",ROUND(P64/$P$11*100,2)),"") | R64: =IFERROR(IF(Q64="","",ROUND(Q64*$R$11,2)),"") | AC64: =IF(COUNT($S64:$AB64)=0,"",SUM($S64:$AB64)) | AD64: =IFERROR(IF(AC64="","",ROUND(AC64/$AC$11*100,2)),"") | AE64: =IFERROR(IF(AD64="","",ROUND(AD64*$AE$11,2)),"") | AG64: =IFERROR(IF(AF64="","",ROUND(AF64/$AF$11*100,2)),"") | AH64: =IFERROR(IF(AG64="","",ROUND(AG64*$AH$11,2)),"") | AI64: =IFERROR(R64+AE64+AH64,"") | AJ64: =IFERROR(VLOOKUP(AI64,'Helper(IMPORTANT!)'!$AX$1:$AY$41,2,TRUE),"")
A65: 2 | B65: ='INPUT DATA'!B65 | P65: =IF(COUNT($F65:$O65)=0,"",SUM($F65:$O65)) | Q65: =IFERROR(IF(P65="","",ROUND(P65/$P$11*100,2)),"") | R65: =IFERROR(IF(Q65="","",ROUND(Q65*$R$11,2)),"") | AC65: =IF(COUNT($S65:$AB65)=0,"",SUM($S65:$AB65)) | AD65: =IFERROR(IF(AC65="","",ROUND(AC65/$AC$11*100,2)),"") | AE65: =IFERROR(IF(AD65="","",ROUND(AD65*$AE$11,2)),"") | AG65: =IFERROR(IF(AF65="","",ROUND(AF65/$AF$11*100,2)),"") | AH65: =IFERROR(IF(AG65="","",ROUND(AG65*$AH$11,2)),"") | AI65: =IFERROR(R65+AE65+AH65,"") | AJ65: =IFERROR(VLOOKUP(AI65,'Helper(IMPORTANT!)'!$AX$1:$AY$41,2,TRUE),"")
A66: 3 | B66: ='INPUT DATA'!B66 | P66: =IF(COUNT($F66:$O66)=0,"",SUM($F66:$O66)) | Q66: =IFERROR(IF(P66="","",ROUND(P66/$P$11*100,2)),"") | R66: =IFERROR(IF(Q66="","",ROUND(Q66*$R$11,2)),"") | AC66: =IF(COUNT($S66:$AB66)=0,"",SUM($S66:$AB66)) | AD66: =IFERROR(IF(AC66="","",ROUND(AC66/$AC$11*100,2)),"") | AE66: =IFERROR(IF(AD66="","",ROUND(AD66*$AE$11,2)),"") | AG66: =IFERROR(IF(AF66="","",ROUND(AF66/$AF$11*100,2)),"") | AH66: =IFERROR(IF(AG66="","",ROUND(AG66*$AH$11,2)),"") | AI66: =IFERROR(R66+AE66+AH66,"") | AJ66: =IFERROR(VLOOKUP(AI66,'Helper(IMPORTANT!)'!$AX$1:$AY$41,2,TRUE),"")
A67: 4 | B67: ='INPUT DATA'!B67 | P67: =IF(COUNT($F67:$O67)=0,"",SUM($F67:$O67)) | Q67: =IFERROR(IF(P67="","",ROUND(P67/$P$11*100,2)),"") | R67: =IFERROR(IF(Q67="","",ROUND(Q67*$R$11,2)),"") | AC67: =IF(COUNT($S67:$AB67)=0,"",SUM($S67:$AB67)) | AD67: =IFERROR(IF(AC67="","",ROUND(AC67/$AC$11*100,2)),"") | AE67: =IFERROR(IF(AD67="","",ROUND(AD67*$AE$11,2)),"") | AG67: =IFERROR(IF(AF67="","",ROUND(AF67/$AF$11*100,2)),"") | AH67: =IFERROR(IF(AG67="","",ROUND(AG67*$AH$11,2)),"") | AI67: =IFERROR(R67+AE67+AH67,"") | AJ67: =IFERROR(VLOOKUP(AI67,'Helper(IMPORTANT!)'!$AX$1:$AY$41,2,TRUE),"")
A68: 5 | B68: ='INPUT DATA'!B68 | P68: =IF(COUNT($F68:$O68)=0,"",SUM($F68:$O68)) | Q68: =IFERROR(IF(P68="","",ROUND(P68/$P$11*100,2)),"") | R68: =IFERROR(IF(Q68="","",ROUND(Q68*$R$11,2)),"") | AC68: =IF(COUNT($S68:$AB68)=0,"",SUM($S68:$AB68)) | AD68: =IFERROR(IF(AC68="","",ROUND(AC68/$AC$11*100,2)),"") | AE68: =IFERROR(IF(AD68="","",ROUND(AD68*$AE$11,2)),"") | AG68: =IFERROR(IF(AF68="","",ROUND(AF68/$AF$11*100,2)),"") | AH68: =IFERROR(IF(AG68="","",ROUND(AG68*$AH$11,2)),"") | AI68: =IFERROR(R68+AE68+AH68,"") | AJ68: =IFERROR(VLOOKUP(AI68,'Helper(IMPORTANT!)'!$AX$1:$AY$41,2,TRUE),"")
A69: 6 | B69: ='INPUT DATA'!B69 | P69: =IF(COUNT($F69:$O69)=0,"",SUM($F69:$O69)) | Q69: =IFERROR(IF(P69="","",ROUND(P69/$P$11*100,2)),"") | R69: =IFERROR(IF(Q69="","",ROUND(Q69*$R$11,2)),"") | AC69: =IF(COUNT($S69:$AB69)=0,"",SUM($S69:$AB69)) | AD69: =IFERROR(IF(AC69="","",ROUND(AC69/$AC$11*100,2)),"") | AE69: =IFERROR(IF(AD69="","",ROUND(AD69*$AE$11,2)),"") | AG69: =IFERROR(IF(AF69="","",ROUND(AF69/$AF$11*100,2)),"") | AH69: =IFERROR(IF(AG69="","",ROUND(AG69*$AH$11,2)),"") | AI69: =IFERROR(R69+AE69+AH69,"") | AJ69: =IFERROR(VLOOKUP(AI69,'Helper(IMPORTANT!)'!$AX$1:$AY$41,2,TRUE),"")
A70: 7 | B70: ='INPUT DATA'!B70 | P70: =IF(COUNT($F70:$O70)=0,"",SUM($F70:$O70)) | Q70: =IFERROR(IF(P70="","",ROUND(P70/$P$11*100,2)),"") | R70: =IFERROR(IF(Q70="","",ROUND(Q70*$R$11,2)),"") | AC70: =IF(COUNT($S70:$AB70)=0,"",SUM($S70:$AB70)) | AD70: =IFERROR(IF(AC70="","",ROUND(AC70/$AC$11*100,2)),"") | AE70: =IFERROR(IF(AD70="","",ROUND(AD70*$AE$11,2)),"") | AG70: =IFERROR(IF(AF70="","",ROUND(AF70/$AF$11*100,2)),"") | AH70: =IFERROR(IF(AG70="","",ROUND(AG70*$AH$11,2)),"") | AI70: =IFERROR(R70+AE70+AH70,"") | AJ70: =IFERROR(VLOOKUP(AI70,'Helper(IMPORTANT!)'!$AX$1:$AY$41,2,TRUE),"")
A71: 8 | B71: ='INPUT DATA'!B71 | P71: =IF(COUNT($F71:$O71)=0,"",SUM($F71:$O71)) | Q71: =IFERROR(IF(P71="","",ROUND(P71/$P$11*100,2)),"") | R71: =IFERROR(IF(Q71="","",ROUND(Q71*$R$11,2)),"") | AC71: =IF(COUNT($S71:$AB71)=0,"",SUM($S71:$AB71)) | AD71: =IFERROR(IF(AC71="","",ROUND(AC71/$AC$11*100,2)),"") | AE71: =IFERROR(IF(AD71="","",ROUND(AD71*$AE$11,2)),"") | AG71: =IFERROR(IF(AF71="","",ROUND(AF71/$AF$11*100,2)),"") | AH71: =IFERROR(IF(AG71="","",ROUND(AG71*$AH$11,2)),"") | AI71: =IFERROR(R71+AE71+AH71,"") | AJ71: =IFERROR(VLOOKUP(AI71,'Helper(IMPORTANT!)'!$AX$1:$AY$41,2,TRUE),"")
A72: 9 | B72: ='INPUT DATA'!B72 | P72: =IF(COUNT($F72:$O72)=0,"",SUM($F72:$O72)) | Q72: =IFERROR(IF(P72="","",ROUND(P72/$P$11*100,2)),"") | R72: =IFERROR(IF(Q72="","",ROUND(Q72*$R$11,2)),"") | AC72: =IF(COUNT($S72:$AB72)=0,"",SUM($S72:$AB72)) | AD72: =IFERROR(IF(AC72="","",ROUND(AC72/$AC$11*100,2)),"") | AE72: =IFERROR(IF(AD72="","",ROUND(AD72*$AE$11,2)),"") | AG72: =IFERROR(IF(AF72="","",ROUND(AF72/$AF$11*100,2)),"") | AH72: =IFERROR(IF(AG72="","",ROUND(AG72*$AH$11,2)),"") | AI72: =IFERROR(R72+AE72+AH72,"") | AJ72: =IFERROR(VLOOKUP(AI72,'Helper(IMPORTANT!)'!$AX$1:$AY$41,2,TRUE),"")
A73: 10 | B73: ='INPUT DATA'!B73 | P73: =IF(COUNT($F73:$O73)=0,"",SUM($F73:$O73)) | Q73: =IFERROR(IF(P73="","",ROUND(P73/$P$11*100,2)),"") | R73: =IFERROR(IF(Q73="","",ROUND(Q73*$R$11,2)),"") | AC73: =IF(COUNT($S73:$AB73)=0,"",SUM($S73:$AB73)) | AD73: =IFERROR(IF(AC73="","",ROUND(AC73/$AC$11*100,2)),"") | AE73: =IFERROR(IF(AD73="","",ROUND(AD73*$AE$11,2)),"") | AG73: =IFERROR(IF(AF73="","",ROUND(AF73/$AF$11*100,2)),"") | AH73: =IFERROR(IF(AG73="","",ROUND(AG73*$AH$11,2)),"") | AI73: =IFERROR(R73+AE73+AH73,"") | AJ73: =IFERROR(VLOOKUP(AI73,'Helper(IMPORTANT!)'!$AX$1:$AY$41,2,TRUE),"")
A74: 11 | B74: ='INPUT DATA'!B74 | P74: =IF(COUNT($F74:$O74)=0,"",SUM($F74:$O74)) | Q74: =IFERROR(IF(P74="","",ROUND(P74/$P$11*100,2)),"") | R74: =IFERROR(IF(Q74="","",ROUND(Q74*$R$11,2)),"") | AC74: =IF(COUNT($S74:$AB74)=0,"",SUM($S74:$AB74)) | AD74: =IFERROR(IF(AC74="","",ROUND(AC74/$AC$11*100,2)),"") | AE74: =IFERROR(IF(AD74="","",ROUND(AD74*$AE$11,2)),"") | AG74: =IFERROR(IF(AF74="","",ROUND(AF74/$AF$11*100,2)),"") | AH74: =IFERROR(IF(AG74="","",ROUND(AG74*$AH$11,2)),"") | AI74: =IFERROR(R74+AE74+AH74,"") | AJ74: =IFERROR(VLOOKUP(AI74,'Helper(IMPORTANT!)'!$AX$1:$AY$41,2,TRUE),"")
A75: 12 | B75: ='INPUT DATA'!B75 | P75: =IF(COUNT($F75:$O75)=0,"",SUM($F75:$O75)) | Q75: =IFERROR(IF(P75="","",ROUND(P75/$P$11*100,2)),"") | R75: =IFERROR(IF(Q75="","",ROUND(Q75*$R$11,2)),"") | AC75: =IF(COUNT($S75:$AB75)=0,"",SUM($S75:$AB75)) | AD75: =IFERROR(IF(AC75="","",ROUND(AC75/$AC$11*100,2)),"") | AE75: =IFERROR(IF(AD75="","",ROUND(AD75*$AE$11,2)),"") | AG75: =IFERROR(IF(AF75="","",ROUND(AF75/$AF$11*100,2)),"") | AH75: =IFERROR(IF(AG75="","",ROUND(AG75*$AH$11,2)),"") | AI75: =IFERROR(R75+AE75+AH75,"") | AJ75: =IFERROR(VLOOKUP(AI75,'Helper(IMPORTANT!)'!$AX$1:$AY$41,2,TRUE),"")
... A113: 50 | B113: ='INPUT DATA'!B113 | P113: =IF(COUNT($F113:$O113)=0,"",SUM($F113:$O113)) | Q113: =IFERROR(IF(P113="","",ROUND(P113/$P$11*100,2)),"") | R113: =IFERROR(IF(Q113="","",ROUND(Q113*$R$11,2)),"") | AC113: =IF(COUNT($S113:$AB113)=0,"",SUM($S113:$AB113)) | AD113: =IFERROR(IF(AC113="","",ROUND(AC113/$AC$11*100,2)),"") | AE113: =IFERROR(IF(AD113="","",ROUND(AD113*$AE$11,2)),"") | AG113: =IFERROR(IF(AF113="","",ROUND(AF113/$AF$11*100,2)),"") | AH113: =IFERROR(IF(AG113="","",ROUND(AG113*$AH$11,2)),"") | AI113: =IFERROR(R113+AE113+AH113,"") | AJ113: =IFERROR(VLOOKUP(AI113,'Helper(IMPORTANT!)'!$AX$1:$AY$41,2,TRUE),"")

Sheet Final Semestral Grade
A1: Final Semestral Grades
C5: REGION | G5: ='INPUT DATA'!G4 | L5: DIVISION | O5: ='INPUT DATA'!O4 | S5: SCHOOL ID | W5: ='INPUT DATA'!X5
B6: SCHOOL NAME | G6: ='INPUT DATA'!G5 | S6: SCHOOL YEAR | W6: ='INPUT DATA'!AG5
A8: LEARNERS' NAMES | F8: GRADE & SECTION: | K8: ='INPUT DATA'!K7 | S8: SEMESTER: | V8: ='INPUT DATA'!S8
S9: SUBJECT: | V9: ='INPUT DATA'!AE7
F10: TEACHER: | I10: ='INPUT DATA'!S7 | S10: TRACK: | V10: ='INPUT DATA'!AE8
F11: =IF('INPUT DATA'!S8="","",IF('INPUT DATA'!S8="1ST","FIRST QUARTER",IF('INPUT DATA'!S8="2ND","THIRD QUARTER"))) | N11: =IF('INPUT DATA'!S8="","",IF('INPUT DATA'!S8="1ST","SECOND QUARTER",IF('INPUT DATA'!S8="2ND","FOURTH QUARTER"))) | V11: =IF('INPUT DATA'!S8="","",IF('INPUT DATA'!S8="1ST","FIRST SEMESTER FINAL GRADES",IF('INPUT DATA'!S8="2ND","SECOND SEMESTER FINAL GRADES"))) | Z11: REMARK
A12: MALE
A13: 1 | B13: ='INPUT DATA'!B13 | F13: ='1ST'!AJ13 | N13: ='2ND'!AJ13 | V13: =IF(OR(F13="",N13=""),"",IF(ISERROR(ROUND(AVERAGE(F13,N13),0)),"",ROUND(AVERAGE(F13,N13),0))) | Z13: =IF(OR($F13="",N13="",$V13=""),"",IF($V13>=75,"PASSED","FAILED"))
A14: 2 | B14: ='INPUT DATA'!B14 | F14: ='1ST'!AJ14 | N14: ='2ND'!AJ14 | V14: =IF(OR(F14="",N14=""),"",IF(ISERROR(ROUND(AVERAGE(F14,N14),0)),"",ROUND(AVERAGE(F14,N14),0))) | Z14: =IF(OR($F14="",N14="",$V14=""),"",IF($V14>=75,"PASSED","FAILED"))
A15: 3 | B15: ='INPUT DATA'!B15 | F15: ='1ST'!AJ15 | N15: ='2ND'!AJ15 | V15: =IF(OR(F15="",N15=""),"",IF(ISERROR(ROUND(AVERAGE(F15,N15),0)),"",ROUND(AVERAGE(F15,N15),0))) | Z15: =IF(OR($F15="",N15="",$V15=""),"",IF($V15>=75,"PASSED","FAILED"))
A16: 4 | B16: ='INPUT DATA'!B16 | F16: ='1ST'!AJ16 | N16: ='2ND'!AJ16 | V16: =IF(OR(F16="",N16=""),"",IF(ISERROR(ROUND(AVERAGE(F16,N16),0)),"",ROUND(AVERAGE(F16,N16),0))) | Z16: =IF(OR($F16="",N16="",$V16=""),"",IF($V16>=75,"PASSED","FAILED"))
A17: 5 | B17: ='INPUT DATA'!B17 | F17: ='1ST'!AJ17 | N17: ='2ND'!AJ17 | V17: =IF(OR(F17="",N17=""),"",IF(ISERROR(ROUND(AVERAGE(F17,N17),0)),"",ROUND(AVERAGE(F17,N17),0))) | Z17: =IF(OR($F17="",N17="",$V17=""),"",IF($V17>=75,"PASSED","FAILED"))
A18: 6 | B18: ='INPUT DATA'!B18 | F18: ='1ST'!AJ18 | N18: ='2ND'!AJ18 | V18: =IF(OR(F18="",N18=""),"",IF(ISERROR(ROUND(AVERAGE(F18,N18),0)),"",ROUND(AVERAGE(F18,N18),0))) | Z18: =IF(OR($F18="",N18="",$V18=""),"",IF($V18>=75,"PASSED","FAILED"))
A19: 7 | B19: ='INPUT DATA'!B19 | F19: ='1ST'!AJ19 | N19: ='2ND'!AJ19 | V19: =IF(OR(F19="",N19=""),"",IF(ISERROR(ROUND(AVERAGE(F19,N19),0)),"",ROUND(AVERAGE(F19,N19),0))) | Z19: =IF(OR($F19="",N19="",$V19=""),"",IF($V19>=75,"PASSED","FAILED"))
A20: 8 | B20: ='INPUT DATA'!B20 | F20: ='1ST'!AJ20 | N20: ='2ND'!AJ20 | V20: =IF(OR(F20="",N20=""),"",IF(ISERROR(ROUND(AVERAGE(F20,N20),0)),"",ROUND(AVERAGE(F20,N20),0))) | Z20: =IF(OR($F20="",N20="",$V20=""),"",IF($V20>=75,"PASSED","FAILED"))
A21: 9 | B21: ='INPUT DATA'!B21 | F21: ='1ST'!AJ21 | N21: ='2ND'!AJ21 | V21: =IF(OR(F21="",N21=""),"",IF(ISERROR(ROUND(AVERAGE(F21,N21),0)),"",ROUND(AVERAGE(F21,N21),0))) | Z21: =IF(OR($F21="",N21="",$V21=""),"",IF($V21>=75,"PASSED","FAILED"))
A22: 10 | B22: ='INPUT DATA'!B22 | F22: ='1ST'!AJ22 | N22: ='2ND'!AJ22 | V22: =IF(OR(F22="",N22=""),"",IF(ISERROR(ROUND(AVERAGE(F22,N22),0)),"",ROUND(AVERAGE(F22,N22),0))) | Z22: =IF(OR($F22="",N22="",$V22=""),"",IF($V22>=75,"PASSED","FAILED"))
A23: 11 | B23: ='INPUT DATA'!B23 | F23: ='1ST'!AJ23 | N23: ='2ND'!AJ23 | V23: =IF(OR(F23="",N23=""),"",IF(ISERROR(ROUND(AVERAGE(F23,N23),0)),"",ROUND(AVERAGE(F23,N23),0))) | Z23: =IF(OR($F23="",N23="",$V23=""),"",IF($V23>=75,"PASSED","FAILED"))
A24: 12 | B24: ='INPUT DATA'!B24 | F24: ='1ST'!AJ24 | N24: ='2ND'!AJ24 | V24: =IF(OR(F24="",N24=""),"",IF(ISERROR(ROUND(AVERAGE(F24,N24),0)),"",ROUND(AVERAGE(F24,N24),0))) | Z24: =IF(OR($F24="",N24="",$V24=""),"",IF($V24>=75,"PASSED","FAILED"))
... A62: 50 | B62: ='INPUT DATA'!B62 | F62: ='1ST'!AJ62 | N62: ='2ND'!AJ62 | V62: =IF(OR(F62="",N62=""),"",IF(ISERROR(ROUND(AVERAGE(F62,N62),0)),"",ROUND(AVERAGE(F62,N62),0))) | Z62: =IF(OR($F62="",N62="",$V62=""),"",IF($V62>=75,"PASSED","FAILED"))
A63: FEMALE
A64: 1 | B64: ='INPUT DATA'!B64 | F64: ='1ST'!AJ64 | N64: ='2ND'!AJ64 | V64: =IF(OR(F64="",N64=""),"",IF(ISERROR(ROUND(AVERAGE(F64,N64),0)),"",ROUND(AVERAGE(F64,N64),0))) | Z64: =IF(OR($F64="",N64="",$V64=""),"",IF($V64>=75,"PASSED","FAILED"))
A65: 2 | B65: ='INPUT DATA'!B65 | F65: ='1ST'!AJ65 | N65: ='2ND'!AJ65 | V65: =IF(OR(F65="",N65=""),"",IF(ISERROR(ROUND(AVERAGE(F65,N65),0)),"",ROUND(AVERAGE(F65,N65),0))) | Z65: =IF(OR($F65="",N65="",$V65=""),"",IF($V65>=75,"PASSED","FAILED"))
A66: 3 | B66: ='INPUT DATA'!B66 | F66: ='1ST'!AJ66 | N66: ='2ND'!AJ66 | V66: =IF(OR(F66="",N66=""),"",IF(ISERROR(ROUND(AVERAGE(F66,N66),0)),"",ROUND(AVERAGE(F66,N66),0))) | Z66: =IF(OR($F66="",N66="",$V66=""),"",IF($V66>=75,"PASSED","FAILED"))
A67: 4 | B67: ='INPUT DATA'!B67 | F67: ='1ST'!AJ67 | N67: ='2ND'!AJ67 | V67: =IF(OR(F67="",N67=""),"",IF(ISERROR(ROUND(AVERAGE(F67,N67),0)),"",ROUND(AVERAGE(F67,N67),0))) | Z67: =IF(OR($F67="",N67="",$V67=""),"",IF($V67>=75,"PASSED","FAILED"))
A68: 5 | B68: ='INPUT DATA'!B68 | F68: ='1ST'!AJ68 | N68: ='2ND'!AJ68 | V68: =IF(OR(F68="",N68=""),"",IF(ISERROR(ROUND(AVERAGE(F68,N68),0)),"",ROUND(AVERAGE(F68,N68),0))) | Z68: =IF(OR($F68="",N68="",$V68=""),"",IF($V68>=75,"PASSED","FAILED"))
A69: 6 | B69: ='INPUT DATA'!B69 | F69: ='1ST'!AJ69 | N69: ='2ND'!AJ69 | V69: =IF(OR(F69="",N69=""),"",IF(ISERROR(ROUND(AVERAGE(F69,N69),0)),"",ROUND(AVERAGE(F69,N69),0))) | Z69: =IF(OR($F69="",N69="",$V69=""),"",IF($V69>=75,"PASSED","FAILED"))
A70: 7 | B70: ='INPUT DATA'!B70 | F70: ='1ST'!AJ70 | N70: ='2ND'!AJ70 | V70: =IF(OR(F70="",N70=""),"",IF(ISERROR(ROUND(AVERAGE(F70,N70),0)),"",ROUND(AVERAGE(F70,N70),0))) | Z70: =IF(OR($F70="",N70="",$V70=""),"",IF($V70>=75,"PASSED","FAILED"))
A71: 8 | B71: ='INPUT DATA'!B71 | F71: ='1ST'!AJ71 | N71: ='2ND'!AJ71 | V71: =IF(OR(F71="",N71=""),"",IF(ISERROR(ROUND(AVERAGE(F71,N71),0)),"",ROUND(AVERAGE(F71,N71),0))) | Z71: =IF(OR($F71="",N71="",$V71=""),"",IF($V71>=75,"PASSED","FAILED"))
A72: 9 | B72: ='INPUT DATA'!B72 | F72: ='1ST'!AJ72 | N72: ='2ND'!AJ72 | V72: =IF(OR(F72="",N72=""),"",IF(ISERROR(ROUND(AVERAGE(F72,N72),0)),"",ROUND(AVERAGE(F72,N72),0))) | Z72: =IF(OR($F72="",N72="",$V72=""),"",IF($V72>=75,"PASSED","FAILED"))
A73: 10 | B73: ='INPUT DATA'!B73 | F73: ='1ST'!AJ73 | N73: ='2ND'!AJ73 | V73: =IF(OR(F73="",N73=""),"",IF(ISERROR(ROUND(AVERAGE(F73,N73),0)),"",ROUND(AVERAGE(F73,N73),0))) | Z73: =IF(OR($F73="",N73="",$V73=""),"",IF($V73>=75,"PASSED","FAILED"))
A74: 11 | B74: ='INPUT DATA'!B74 | F74: ='1ST'!AJ74 | N74: ='2ND'!AJ74 | V74: =IF(OR(F74="",N74=""),"",IF(ISERROR(ROUND(AVERAGE(F74,N74),0)),"",ROUND(AVERAGE(F74,N74),0))) | Z74: =IF(OR($F74="",N74="",$V74=""),"",IF($V74>=75,"PASSED","FAILED"))
A75: 12 | B75: ='INPUT DATA'!B75 | F75: ='1ST'!AJ75 | N75: ='2ND'!AJ75 | V75: =IF(OR(F75="",N75=""),"",IF(ISERROR(ROUND(AVERAGE(F75,N75),0)),"",ROUND(AVERAGE(F75,N75),0))) | Z75: =IF(OR($F75="",N75="",$V75=""),"",IF($V75>=75,"PASSED","FAILED"))
... A113: 50 | B113: ='INPUT DATA'!B113 | F113: ='1ST'!AJ113 | N113: ='2ND'!AJ113 | V113: =IF(OR(F113="",N113=""),"",IF(ISERROR(ROUND(AVERAGE(F113,N113),0)),"",ROUND(AVERAGE(F113,N113),0))) | Z113: =IF(OR($F113="",N113="",$V113=""),"",IF($V113>=75,"PASSED","FAILED"))

Sheet Helper(IMPORTANT!)
A1: 1 | B1: 2 | C1: 3 | D1: 4 | E1: 5 | F1: 6 | G1: 7 | H1: 8 | I1: 9 | J1: 10 | K1: 1 | L1: 2 | M1: 3 | N1: 4 | O1: 5 | P1: 6 | Q1: 7 | R1: 8 | S1: 9 | T1: 10 | U1: 1 | V1: 1 | W1: 2 | X1: 3 | Y1: 4 | Z1: 5 | AA1: 6 | AB1: 7 | AC1: 8 | AD1: 9 | AE1: 10 | AF1: 1 | AG1: 2 | AH1: 3 | AI1: 4 | AJ1: 5 | AK1: 6 | AL1: 7 | AM1: 8 | AN1: 9 | AO1: 10 | AP1: 1 | AQ1: SUBJECTS | AR1: WRITTEN WORKS | AS1: PERFORMANCE TASKS | AT1: QUARTERLY ASSESSMENT | AU1: WW | AV1: PT | AW1: QA | AX1: 0 | AY1: 60
A2: =IF('1ST'!F11="","",'1ST'!F11) | B2: =IF('1ST'!G11="","",'1ST'!G11) | C2: =IF('1ST'!H11="","",'1ST'!H11) | D2: =IF('1ST'!I11="","",'1ST'!I11) | E2: =IF('1ST'!J11="","",'1ST'!J11) | F2: =IF('1ST'!K11="","",'1ST'!K11) | G2: =IF('1ST'!L11="","",'1ST'!L11) | H2: =IF('1ST'!M11="","",'1ST'!M11) | ... J2: =IF('1ST'!O11="","",'1ST'!O11) | K2: =IF('1ST'!S11="","",'1ST'!S11) | L2: =IF('1ST'!T11="","",'1ST'!T11) | M2: =IF('1ST'!U11="","",'1ST'!U11) | N2: =IF('1ST'!V11="","",'1ST'!V11) | O2: =IF('1ST'!W11="","",'1ST'!W11) | P2: =IF('1ST'!X11="","",'1ST'!X11) | Q2: =IF('1ST'!Y11="","",'1ST'!Y11) | R2: =IF('1ST'!Z11="","",'1ST'!Z11) | ... T2: =IF('1ST'!AB11="","",'1ST'!AB11) | U2: =IF('1ST'!AF11="","",'1ST'!AF11) | V2: =IF('2ND'!F11="","",'2ND'!F11) | W2: =IF('2ND'!G11="","",'2ND'!G11) | X2: =IF('2ND'!H11="","",'2ND'!H11) | Y2: =IF('2ND'!I11="","",'2ND'!I11) | Z2: =IF('2ND'!J11="","",'2ND'!J11) | AA2: =IF('2ND'!K11="","",'2ND'!K11) | AB2: =IF('2ND'!L11="","",'2ND'!L11) | AC2: =IF('2ND'!M11="","",'2ND'!M11) | ... AE2: =IF('2ND'!O11="","",'2ND'!O11) | AF2: =IF('2ND'!S11="","",'2ND'!S11) | AG2: =IF('2ND'!T11="","",'2ND'!T11) | AH2: =IF('2ND'!U11="","",'2ND'!U11) | AI2: =IF('2ND'!V11="","",'2ND'!V11) | AJ2: =IF('2ND'!W11="","",'2ND'!W11) | AK2: =IF('2ND'!X11="","",'2ND'!X11) | AL2: =IF('2ND'!Y11="","",'2ND'!Y11) | AM2: =IF('2ND'!Z11="","",'2ND'!Z11) | ... AO2: =IF('2ND'!AB11="","",'2ND'!AB11) | AP2: =IF('2ND'!AF11="","",'2ND'!AF11) | AQ2: Core Subject (All Tracks) | AR2: WRITTEN WORK (25%) | AS2: PERFORMANCE TASKS (50%) | AT2: QUARTERLY ASSESSMENT (25%) | AU2: 0.25 | AV2: 0.5 | AW2: 0.25 | AX2: 4 | AY2: 61
A3: =IFERROR(IF(IF(A2="","",A2-1)<0,"",A2-1),"") | B3: =IFERROR(IF(IF(B2="","",B2-1)<0,"",B2-1),"") | C3: =IFERROR(IF(IF(C2="","",C2-1)<0,"",C2-1),"") | D3: =IFERROR(IF(IF(D2="","",D2-1)<0,"",D2-1),"") | E3: =IFERROR(IF(IF(E2="","",E2-1)<0,"",E2-1),"") | F3: =IFERROR(IF(IF(F2="","",F2-1)<0,"",F2-1),"") | G3: =IFERROR(IF(IF(G2="","",G2-1)<0,"",G2-1),"") | H3: =IFERROR(IF(IF(H2="","",H2-1)<0,"",H2-1),"") | ... AP3: =IFERROR(IF(IF(AP2="","",AP2-1)<0,"",AP2-1),"") | AQ3: Academic Track (except Immersion) | AR3: WRITTEN WORK (25%) | AS3: PERFORMANCE TASKS (45%) | AT3: QUARTERLY ASSESSMENT (30%) | AU3: 0.25 | AV3: 0.45 | AW3: 0.3 | AX3: 8 | AY3: 62
A4: =IFERROR(IF(IF(A3="","",A3-1)<0,"",A3-1),"") | B4: =IFERROR(IF(IF(B3="","",B3-1)<0,"",B3-1),"") | C4: =IFERROR(IF(IF(C3="","",C3-1)<0,"",C3-1),"") | D4: =IFERROR(IF(IF(D3="","",D3-1)<0,"",D3-1),"") | E4: =IFERROR(IF(IF(E3="","",E3-1)<0,"",E3-1),"") | F4: =IFERROR(IF(IF(F3="","",F3-1)<0,"",F3-1),"") | G4: =IFERROR(IF(IF(G3="","",G3-1)<0,"",G3-1),"") | H4: =IFERROR(IF(IF(H3="","",H3-1)<0,"",H3-1),"") | ... AP4: =IFERROR(IF(IF(AP3="","",AP3-1)<0,"",AP3-1),"") | AQ4: Work Immersion/ Culminating Activity (for Academic Track) | AR4: WRITTEN WORK (35%) | AS4: PERFORMANCE TASKS (40%) | AT4: QUARTERLY ASSESSMENT (25%) | AU4: 0.35 | AV4: 0.4 | AW4: 0.25 | AX4: 12 | AY4: 63
A5: =IFERROR(IF(IF(A4="","",A4-1)<0,"",A4-1),"") | B5: =IFERROR(IF(IF(B4="","",B4-1)<0,"",B4-1),"") | C5: =IFERROR(IF(IF(C4="","",C4-1)<0,"",C4-1),"") | D5: =IFERROR(IF(IF(D4="","",D4-1)<0,"",D4-1),"") | E5: =IFERROR(IF(IF(E4="","",E4-1)<0,"",E4-1),"") | F5: =IFERROR(IF(IF(F4="","",F4-1)<0,"",F4-1),"") | G5: =IFERROR(IF(IF(G4="","",G4-1)<0,"",G4-1),"") | H5: =IFERROR(IF(IF(H4="","",H4-1)<0,"",H4-1),"") | ... AP5: =IFERROR(IF(IF(AP4="","",AP4-1)<0,"",AP4-1),"") | AQ5: TVL/ Sports/ Arts and Design Track | AR5: WRITTEN WORK (20%) | AS5: PERFORMANCE TASKS (60%) | AT5: QUARTERLY ASSESSMENT (20%) | AU5: 0.2 | AV5: 0.6 | AW5: 0.2 | AX5: 16 | AY5: 64
A6: =IFERROR(IF(IF(A5="","",A5-1)<0,"",A5-1),"") | B6: =IFERROR(IF(IF(B5="","",B5-1)<0,"",B5-1),"") | C6: =IFERROR(IF(IF(C5="","",C5-1)<0,"",C5-1),"") | D6: =IFERROR(IF(IF(D5="","",D5-1)<0,"",D5-1),"") | E6: =IFERROR(IF(IF(E5="","",E5-1)<0,"",E5-1),"") | F6: =IFERROR(IF(IF(F5="","",F5-1)<0,"",F5-1),"") | G6: =IFERROR(IF(IF(G5="","",G5-1)<0,"",G5-1),"") | H6: =IFERROR(IF(IF(H5="","",H5-1)<0,"",H5-1),"") | ... AP6: =IFERROR(IF(IF(AP5="","",AP5-1)<0,"",AP5-1),"") | AX6: 20 | AY6: 65
A7: =IFERROR(IF(IF(A6="","",A6-1)<0,"",A6-1),"") | B7: =IFERROR(IF(IF(B6="","",B6-1)<0,"",B6-1),"") | C7: =IFERROR(IF(IF(C6="","",C6-1)<0,"",C6-1),"") | D7: =IFERROR(IF(IF(D6="","",D6-1)<0,"",D6-1),"") | E7: =IFERROR(IF(IF(E6="","",E6-1)<0,"",E6-1),"") | F7: =IFERROR(IF(IF(F6="","",F6-1)<0,"",F6-1),"") | G7: =IFERROR(IF(IF(G6="","",G6-1)<0,"",G6-1),"") | H7: =IFERROR(IF(IF(H6="","",H6-1)<0,"",H6-1),"") | ... AP7: =IFERROR(IF(IF(AP6="","",AP6-1)<0,"",AP6-1),"") | AQ7: yongbarba@gmail.com | AX7: 24 | AY7: 66
A8: =IFERROR(IF(IF(A7="","",A7-1)<0,"",A7-1),"") | B8: =IFERROR(IF(IF(B7="","",B7-1)<0,"",B7-1),"") | C8: =IFERROR(IF(IF(C7="","",C7-1)<0,"",C7-1),"") | D8: =IFERROR(IF(IF(D7="","",D7-1)<0,"",D7-1),"") | E8: =IFERROR(IF(IF(E7="","",E7-1)<0,"",E7-1),"") | F8: =IFERROR(IF(IF(F7="","",F7-1)<0,"",F7-1),"") | G8: =IFERROR(IF(IF(G7="","",G7-1)<0,"",G7-1),"") | H8: =IFERROR(IF(IF(H7="","",H7-1)<0,"",H7-1),"") | ... AP8: =IFERROR(IF(IF(AP7="","",AP7-1)<0,"",AP7-1),"") | AQ8: jose.barba@deped.gov.ph | AX8: 28 | AY8: 67
A9: =IFERROR(IF(IF(A8="","",A8-1)<0,"",A8-1),"") | B9: =IFERROR(IF(IF(B8="","",B8-1)<0,"",B8-1),"") | C9: =IFERROR(IF(IF(C8="","",C8-1)<0,"",C8-1),"") | D9: =IFERROR(IF(IF(D8="","",D8-1)<0,"",D8-1),"") | E9: =IFERROR(IF(IF(E8="","",E8-1)<0,"",E8-1),"") | F9: =IFERROR(IF(IF(F8="","",F8-1)<0,"",F8-1),"") | G9: =IFERROR(IF(IF(G8="","",G8-1)<0,"",G8-1),"") | H9: =IFERROR(IF(IF(H8="","",H8-1)<0,"",H8-1),"") | ... AP9: =IFERROR(IF(IF(AP8="","",AP8-1)<0,"",AP8-1),"") | AX9: 32 | AY9: 68
A10: =IFERROR(IF(IF(A9="","",A9-1)<0,"",A9-1),"") | B10: =IFERROR(IF(IF(B9="","",B9-1)<0,"",B9-1),"") | C10: =IFERROR(IF(IF(C9="","",C9-1)<0,"",C9-1),"") | D10: =IFERROR(IF(IF(D9="","",D9-1)<0,"",D9-1),"") | E10: =IFERROR(IF(IF(E9="","",E9-1)<0,"",E9-1),"") | F10: =IFERROR(IF(IF(F9="","",F9-1)<0,"",F9-1),"") | G10: =IFERROR(IF(IF(G9="","",G9-1)<0,"",G9-1),"") | H10: =IFERROR(IF(IF(H9="","",H9-1)<0,"",H9-1),"") | ... AP10: =IFERROR(IF(IF(AP9="","",AP9-1)<0,"",AP9-1),"") | AX10: 36 | AY10: 69
A11: =IFERROR(IF(IF(A10="","",A10-1)<0,"",A10-1),"") | B11: =IFERROR(IF(IF(B10="","",B10-1)<0,"",B10-1),"") | C11: =IFERROR(IF(IF(C10="","",C10-1)<0,"",C10-1),"") | D11: =IFERROR(IF(IF(D10="","",D10-1)<0,"",D10-1),"") | E11: =IFERROR(IF(IF(E10="","",E10-1)<0,"",E10-1),"") | F11: =IFERROR(IF(IF(F10="","",F10-1)<0,"",F10-1),"") | G11: =IFERROR(IF(IF(G10="","",G10-1)<0,"",G10-1),"") | H11: =IFERROR(IF(IF(H10="","",H10-1)<0,"",H10-1),"") | ... AP11: =IFERROR(IF(IF(AP10="","",AP10-1)<0,"",AP10-1),"") | AX11: 40 | AY11: 70
A12: =IFERROR(IF(IF(A11="","",A11-1)<0,"",A11-1),"") | B12: =IFERROR(IF(IF(B11="","",B11-1)<0,"",B11-1),"") | C12: =IFERROR(IF(IF(C11="","",C11-1)<0,"",C11-1),"") | D12: =IFERROR(IF(IF(D11="","",D11-1)<0,"",D11-1),"") | E12: =IFERROR(IF(IF(E11="","",E11-1)<0,"",E11-1),"") | F12: =IFERROR(IF(IF(F11="","",F11-1)<0,"",F11-1),"") | G12: =IFERROR(IF(IF(G11="","",G11-1)<0,"",G11-1),"") | H12: =IFERROR(IF(IF(H11="","",H11-1)<0,"",H11-1),"") | ... AP12: =IFERROR(IF(IF(AP11="","",AP11-1)<0,"",AP11-1),"") | AX12: 44 | AY12: 71
A13: =IFERROR(IF(IF(A12="","",A12-1)<0,"",A12-1),"") | B13: =IFERROR(IF(IF(B12="","",B12-1)<0,"",B12-1),"") | C13: =IFERROR(IF(IF(C12="","",C12-1)<0,"",C12-1),"") | D13: =IFERROR(IF(IF(D12="","",D12-1)<0,"",D12-1),"") | E13: =IFERROR(IF(IF(E12="","",E12-1)<0,"",E12-1),"") | F13: =IFERROR(IF(IF(F12="","",F12-1)<0,"",F12-1),"") | G13: =IFERROR(IF(IF(G12="","",G12-1)<0,"",G12-1),"") | H13: =IFERROR(IF(IF(H12="","",H12-1)<0,"",H12-1),"") | ... AP13: =IFERROR(IF(IF(AP12="","",AP12-1)<0,"",AP12-1),"") | AX13: 48 | AY13: 72
A14: =IFERROR(IF(IF(A13="","",A13-1)<0,"",A13-1),"") | B14: =IFERROR(IF(IF(B13="","",B13-1)<0,"",B13-1),"") | C14: =IFERROR(IF(IF(C13="","",C13-1)<0,"",C13-1),"") | D14: =IFERROR(IF(IF(D13="","",D13-1)<0,"",D13-1),"") | E14: =IFERROR(IF(IF(E13="","",E13-1)<0,"",E13-1),"") | F14: =IFERROR(IF(IF(F13="","",F13-1)<0,"",F13-1),"") | G14: =IFERROR(IF(IF(G13="","",G13-1)<0,"",G13-1),"") | H14: =IFERROR(IF(IF(H13="","",H13-1)<0,"",H13-1),"") | ... AP14: =IFERROR(IF(IF(AP13="","",AP13-1)<0,"",AP13-1),"") | AX14: 52 | AY14: 73
A15: =IFERROR(IF(IF(A14="","",A14-1)<0,"",A14-1),"") | B15: =IFERROR(IF(IF(B14="","",B14-1)<0,"",B14-1),"") | C15: =IFERROR(IF(IF(C14="","",C14-1)<0,"",C14-1),"") | D15: =IFERROR(IF(IF(D14="","",D14-1)<0,"",D14-1),"") | E15: =IFERROR(IF(IF(E14="","",E14-1)<0,"",E14-1),"") | F15: =IFERROR(IF(IF(F14="","",F14-1)<0,"",F14-1),"") | G15: =IFERROR(IF(IF(G14="","",G14-1)<0,"",G14-1),"") | H15: =IFERROR(IF(IF(H14="","",H14-1)<0,"",H14-1),"") | ... AP15: =IFERROR(IF(IF(AP14="","",AP14-1)<0,"",AP14-1),"") | AX15: 56 | AY15: 74
A16: =IFERROR(IF(IF(A15="","",A15-1)<0,"",A15-1),"") | B16: =IFERROR(IF(IF(B15="","",B15-1)<0,"",B15-1),"") | C16: =IFERROR(IF(IF(C15="","",C15-1)<0,"",C15-1),"") | D16: =IFERROR(IF(IF(D15="","",D15-1)<0,"",D15-1),"") | E16: =IFERROR(IF(IF(E15="","",E15-1)<0,"",E15-1),"") | F16: =IFERROR(IF(IF(F15="","",F15-1)<0,"",F15-1),"") | G16: =IFERROR(IF(IF(G15="","",G15-1)<0,"",G15-1),"") | H16: =IFERROR(IF(IF(H15="","",H15-1)<0,"",H15-1),"") | ... AP16: =IFERROR(IF(IF(AP15="","",AP15-1)<0,"",AP15-1),"") | AX16: 60 | AY16: 75
A17: =IFERROR(IF(IF(A16="","",A16-1)<0,"",A16-1),"") | B17: =IFERROR(IF(IF(B16="","",B16-1)<0,"",B16-1),"") | C17: =IFERROR(IF(IF(C16="","",C16-1)<0,"",C16-1),"") | D17: =IFERROR(IF(IF(D16="","",D16-1)<0,"",D16-1),"") | E17: =IFERROR(IF(IF(E16="","",E16-1)<0,"",E16-1),"") | F17: =IFERROR(IF(IF(F16="","",F16-1)<0,"",F16-1),"") | G17: =IFERROR(IF(IF(G16="","",G16-1)<0,"",G16-1),"") | H17: =IFERROR(IF(IF(H16="","",H16-1)<0,"",H16-1),"") | ... AP17: =IFERROR(IF(IF(AP16="","",AP16-1)<0,"",AP16-1),"") | AX17: 61.6 | AY17: 76
A18: =IFERROR(IF(IF(A17="","",A17-1)<0,"",A17-1),"") | B18: =IFERROR(IF(IF(B17="","",B17-1)<0,"",B17-1),"") | C18: =IFERROR(IF(IF(C17="","",C17-1)<0,"",C17-1),"") | D18: =IFERROR(IF(IF(D17="","",D17-1)<0,"",D17-1),"") | E18: =IFERROR(IF(IF(E17="","",E17-1)<0,"",E17-1),"") | F18: =IFERROR(IF(IF(F17="","",F17-1)<0,"",F17-1),"") | G18: =IFERROR(IF(IF(G17="","",G17-1)<0,"",G17-1),"") | H18: =IFERROR(IF(IF(H17="","",H17-1)<0,"",H17-1),"") | ... AP18: =IFERROR(IF(IF(AP17="","",AP17-1)<0,"",AP17-1),"") | AX18: 63.2 | AY18: 77
A19: =IFERROR(IF(IF(A18="","",A18-1)<0,"",A18-1),"") | B19: =IFERROR(IF(IF(B18="","",B18-1)<0,"",B18-1),"") | C19: =IFERROR(IF(IF(C18="","",C18-1)<0,"",C18-1),"") | D19: =IFERROR(IF(IF(D18="","",D18-1)<0,"",D18-1),"") | E19: =IFERROR(IF(IF(E18="","",E18-1)<0,"",E18-1),"") | F19: =IFERROR(IF(IF(F18="","",F18-1)<0,"",F18-1),"") | G19: =IFERROR(IF(IF(G18="","",G18-1)<0,"",G18-1),"") | H19: =IFERROR(IF(IF(H18="","",H18-1)<0,"",H18-1),"") | ... AP19: =IFERROR(IF(IF(AP18="","",AP18-1)<0,"",AP18-1),"") | AX19: 64.8 | AY19: 78
A20: =IFERROR(IF(IF(A19="","",A19-1)<0,"",A19-1),"") | B20: =IFERROR(IF(IF(B19="","",B19-1)<0,"",B19-1),"") | C20: =IFERROR(IF(IF(C19="","",C19-1)<0,"",C19-1),"") | D20: =IFERROR(IF(IF(D19="","",D19-1)<0,"",D19-1),"") | E20: =IFERROR(IF(IF(E19="","",E19-1)<0,"",E19-1),"") | F20: =IFERROR(IF(IF(F19="","",F19-1)<0,"",F19-1),"") | G20: =IFERROR(IF(IF(G19="","",G19-1)<0,"",G19-1),"") | H20: =IFERROR(IF(IF(H19="","",H19-1)<0,"",H19-1),"") | ... AP20: =IFERROR(IF(IF(AP19="","",AP19-1)<0,"",AP19-1),"") | AX20: 66.4 | AY20: 79
... A41: =IFERROR(IF(IF(A40="","",A40-1)<0,"",A40-1),"") | B41: =IFERROR(IF(IF(B40="","",B40-1)<0,"",B40-1),"") | C41: =IFERROR(IF(IF(C40="","",C40-1)<0,"",C40-1),"") | D41: =IFERROR(IF(IF(D40="","",D40-1)<0,"",D40-1),"") | E41: =IFERROR(IF(IF(E40="","",E40-1)<0,"",E40-1),"") | F41: =IFERROR(IF(IF(F40="","",F40-1)<0,"",F40-1),"") | G41: =IFERROR(IF(IF(G40="","",G40-1)<0,"",G40-1),"") | H41: =IFERROR(IF(IF(H40="","",H40-1)<0,"",H40-1),"") | ... AP41: =IFERROR(IF(IF(AP40="","",AP40-1)<0,"",AP40-1),"") | AX41: 100 | AY41: 100
A42: =IFERROR(IF(IF(A41="","",A41-1)<0,"",A41-1),"") | B42: =IFERROR(IF(IF(B41="","",B41-1)<0,"",B41-1),"") | C42: =IFERROR(IF(IF(C41="","",C41-1)<0,"",C41-1),"") | D42: =IFERROR(IF(IF(D41="","",D41-1)<0,"",D41-1),"") | E42: =IFERROR(IF(IF(E41="","",E41-1)<0,"",E41-1),"") | F42: =IFERROR(IF(IF(F41="","",F41-1)<0,"",F41-1),"") | G42: =IFERROR(IF(IF(G41="","",G41-1)<0,"",G41-1),"") | H42: =IFERROR(IF(IF(H41="","",H41-1)<0,"",H41-1),"") | ... AP42: =IFERROR(IF(IF(AP41="","",AP41-1)<0,"",AP41-1),"")
A43: =IFERROR(IF(IF(A42="","",A42-1)<0,"",A42-1),"") | B43: =IFERROR(IF(IF(B42="","",B42-1)<0,"",B42-1),"") | C43: =IFERROR(IF(IF(C42="","",C42-1)<0,"",C42-1),"") | D43: =IFERROR(IF(IF(D42="","",D42-1)<0,"",D42-1),"") | E43: =IFERROR(IF(IF(E42="","",E42-1)<0,"",E42-1),"") | F43: =IFERROR(IF(IF(F42="","",F42-1)<0,"",F42-1),"") | G43: =IFERROR(IF(IF(G42="","",G42-1)<0,"",G42-1),"") | H43: =IFERROR(IF(IF(H42="","",H42-1)<0,"",H42-1),"") | ... AP43: =IFERROR(IF(IF(AP42="","",AP42-1)<0,"",AP42-1),"")
A44: =IFERROR(IF(IF(A43="","",A43-1)<0,"",A43-1),"") | B44: =IFERROR(IF(IF(B43="","",B43-1)<0,"",B43-1),"") | C44: =IFERROR(IF(IF(C43="","",C43-1)<0,"",C43-1),"") | D44: =IFERROR(IF(IF(D43="","",D43-1)<0,"",D43-1),"") | E44: =IFERROR(IF(IF(E43="","",E43-1)<0,"",E43-1),"") | F44: =IFERROR(IF(IF(F43="","",F43-1)<0,"",F43-1),"") | G44: =IFERROR(IF(IF(G43="","",G43-1)<0,"",G43-1),"") | H44: =IFERROR(IF(IF(H43="","",H43-1)<0,"",H43-1),"") | ... AP44: =IFERROR(IF(IF(AP43="","",AP43-1)<0,"",AP43-1),"")
A45: =IFERROR(IF(IF(A44="","",A44-1)<0,"",A44-1),"") | B45: =IFERROR(IF(IF(B44="","",B44-1)<0,"",B44-1),"") | C45: =IFERROR(IF(IF(C44="","",C44-1)<0,"",C44-1),"") | D45: =IFERROR(IF(IF(D44="","",D44-1)<0,"",D44-1),"") | E45: =IFERROR(IF(IF(E44="","",E44-1)<0,"",E44-1),"") | F45: =IFERROR(IF(IF(F44="","",F44-1)<0,"",F44-1),"") | G45: =IFERROR(IF(IF(G44="","",G44-1)<0,"",G44-1),"") | H45: =IFERROR(IF(IF(H44="","",H44-1)<0,"",H44-1),"") | ... AP45: =IFERROR(IF(IF(AP44="","",AP44-1)<0,"",AP44-1),"")
A46: =IFERROR(IF(IF(A45="","",A45-1)<0,"",A45-1),"") | B46: =IFERROR(IF(IF(B45="","",B45-1)<0,"",B45-1),"") | C46: =IFERROR(IF(IF(C45="","",C45-1)<0,"",C45-1),"") | D46: =IFERROR(IF(IF(D45="","",D45-1)<0,"",D45-1),"") | E46: =IFERROR(IF(IF(E45="","",E45-1)<0,"",E45-1),"") | F46: =IFERROR(IF(IF(F45="","",F45-1)<0,"",F45-1),"") | G46: =IFERROR(IF(IF(G45="","",G45-1)<0,"",G45-1),"") | H46: =IFERROR(IF(IF(H45="","",H45-1)<0,"",H45-1),"") | ... AP46: =IFERROR(IF(IF(AP45="","",AP45-1)<0,"",AP45-1),"")
A47: =IFERROR(IF(IF(A46="","",A46-1)<0,"",A46-1),"") | B47: =IFERROR(IF(IF(B46="","",B46-1)<0,"",B46-1),"") | C47: =IFERROR(IF(IF(C46="","",C46-1)<0,"",C46-1),"") | D47: =IFERROR(IF(IF(D46="","",D46-1)<0,"",D46-1),"") | E47: =IFERROR(IF(IF(E46="","",E46-1)<0,"",E46-1),"") | F47: =IFERROR(IF(IF(F46="","",F46-1)<0,"",F46-1),"") | G47: =IFERROR(IF(IF(G46="","",G46-1)<0,"",G46-1),"") | H47: =IFERROR(IF(IF(H46="","",H46-1)<0,"",H46-1),"") | ... AP47: =IFERROR(IF(IF(AP46="","",AP46-1)<0,"",AP46-1),"")
A48: =IFERROR(IF(IF(A47="","",A47-1)<0,"",A47-1),"") | B48: =IFERROR(IF(IF(B47="","",B47-1)<0,"",B47-1),"") | C48: =IFERROR(IF(IF(C47="","",C47-1)<0,"",C47-1),"") | D48: =IFERROR(IF(IF(D47="","",D47-1)<0,"",D47-1),"") | E48: =IFERROR(IF(IF(E47="","",E47-1)<0,"",E47-1),"") | F48: =IFERROR(IF(IF(F47="","",F47-1)<0,"",F47-1),"") | G48: =IFERROR(IF(IF(G47="","",G47-1)<0,"",G47-1),"") | H48: =IFERROR(IF(IF(H47="","",H47-1)<0,"",H47-1),"") | ... AP48: =IFERROR(IF(IF(AP47="","",AP47-1)<0,"",AP47-1),"")
A49: =IFERROR(IF(IF(A48="","",A48-1)<0,"",A48-1),"") | B49: =IFERROR(IF(IF(B48="","",B48-1)<0,"",B48-1),"") | C49: =IFERROR(IF(IF(C48="","",C48-1)<0,"",C48-1),"") | D49: =IFERROR(IF(IF(D48="","",D48-1)<0,"",D48-1),"") | E49: =IFERROR(IF(IF(E48="","",E48-1)<0,"",E48-1),"") | F49: =IFERROR(IF(IF(F48="","",F48-1)<0,"",F48-1),"") | G49: =IFERROR(IF(IF(G48="","",G48-1)<0,"",G48-1),"") | H49: =IFERROR(IF(IF(H48="","",H48-1)<0,"",H48-1),"") | ... AP49: =IFERROR(IF(IF(AP48="","",AP48-1)<0,"",AP48-1),"")
A50: =IFERROR(IF(IF(A49="","",A49-1)<0,"",A49-1),"") | B50: =IFERROR(IF(IF(B49="","",B49-1)<0,"",B49-1),"") | C50: =IFERROR(IF(IF(C49="","",C49-1)<0,"",C49-1),"") | D50: =IFERROR(IF(IF(D49="","",D49-1)<0,"",D49-1),"") | E50: =IFERROR(IF(IF(E49="","",E49-1)<0,"",E49-1),"") | F50: =IFERROR(IF(IF(F49="","",F49-1)<0,"",F49-1),"") | G50: =IFERROR(IF(IF(G49="","",G49-1)<0,"",G49-1),"") | H50: =IFERROR(IF(IF(H49="","",H49-1)<0,"",H49-1),"") | ... AP50: =IFERROR(IF(IF(AP49="","",AP49-1)<0,"",AP49-1),"")
